Workbook
Name solver_adj: K1.8Q12!$B$61:$B$65
Name solver_adj: K1.8Q8!$B$61:$B$65
Name solver_adj: K1.8Q4!$B$65:$B$68
Name solver_adj: K1.8Q7!$B$61:$B$65
Name solver_adj: K1.8S3!$B$41:$B$45
Name solver_opt: K1.8S1!$F$38
Name solver_adj: K1.8Q2!$B$72:$B$76
Name solver_opt: K1.8Q13!$F$58
Name solver_adj: K1.8Q13!$B$61:$B$65
Name solver_rhs1: #REF!
Name solver_adj: K1.8S4!$B$41:$B$45
Name solver_adj: K1.8O3!$B$33:$B$35
Name solver_opt: K1.8D2!$F$68
Name solver_adj: K1.8Q6!$B$55:$B$58
Name solver_opt: K1.8Q1!$F$19
Name solver_opt: K1.8Q12!$F$58
Name solver_lhs2: #REF!
Name solver_opt: K1.8O2!$F$30
Name solver_adj: K1.8Q11!$B$61:$B$65
Name solver_adj: K1.8D2!$B$71:$B$75
Name solver_opt: K1.8D1!$F$42
Name solver_opt: K1.8Q9!$F$58
Name solver_opt: K1.8Q2!$F$69
Name solver_opt: K1.8Q6!$F$52
Name solver_opt: K1.8Q7!$F$58
Name solver_opt: K1.8Q11!$F$58
Name solver_opt: K1.8D3!$F$38
Name solver_adj: K1.8O1!$B$27:$B$28
Name solver_adj: K1.8Q10!$B$61:$B$65
Name solver_opt: K1.8S4!$F$38
Name solver_opt: K1.8O1!$F$24
Name solver_opt: K1.8Q4!$F$62
Name solver_adj: K1.8S2!$B$41:$B$44
Name solver_adj: K1.8S1!$B$41:$B$44
Name solver_opt: K1.8Q3!$F$62
Name solver_opt: K1.8Q10!$F$58
Name solver_opt: K1.8Q5!$F$42
Name solver_adj: K1.8Q1!$B$22:$B$25
Name solver_adj: K1.8Q9!$B$61:$B$65
Name solver_adj: K1.8D3!$B$41:$B$44
Name solver_opt: K1.8Q8!$F$58
Name solver_lhs1: #REF!
Name solver_adj: K1.8Q5!$B$45:$B$48
Name solver_adj: K1.8D1!$B$45:$B$48
Name solver_adj: K1.8Q3!$B$65:$B$68
Name solver_opt: K1.8S2!$F$38
Name solver_adj: K1.8O2!$B$33:$B$35
Name solver_opt: K1.8S3!$F$38
Name solver_opt: K1.8O3!$F$30
Name solver_rhs2: #REF!

Sheet Sheet1
B1: FF+600 focus | F1: FF+460 focus
B2: 1.8GeV/c | F2: 1.8GeV/c | J2: 1.5GeV/c
B3: TRANS | C3: 2012.2.19 | F3: TRANS
B4: B [kG] | C4: I[A] | D4: B [kG] | F4: B [kG] | G4: I[A] | H4: B [kG] | J4: B [kG] | K4: I[A] | L4: B [kG]
A5: D1 | B5: 11.84605 | C5: -708 | D5: 11.6426 | F5: 11.84605 | G5: -708 | H5: 11.6426 | J5: =F5*1.5/1.8 -> 9.8717083 | K5: -562 | L5: 9.8721
A6: Q1 | B6: 5.5 | C6: -648 | D6: 5.49912 | F6: 5.5 | G6: -648 | H6: 5.49912 | J6: =F6*1.5/1.8 -> 4.5833333 | K6: -534 | L6: 4.584
A7: Q2 | B7: -6.929 | C7: -1214 | D7: -6.93008 | F7: -6.929 | G7: -1214 | H7: -6.93008 | J7: =F7*1.5/1.8 -> -5.7741667 | K7: -996 | L7: -5.7764
A8: D2 | B8: 15.77386 | C8: -1309 | D8: 15.77455 | F8: 15.77386 | G8: -1309 | H8: 15.77455 | J8: =F8*1.5/1.8 -> 13.144883 | K8: -1057 | L8: 13.1502
A9: Q3 | B9: 7.4 | C9: -1221 | D9: 7.39796 | F9: 7.4 | G9: -1221 | H9: 7.39796 | J9: =F9*1.5/1.8 -> 6.1666667 | K9: -1018 | L9: 6.1651
A10: O1 | B10: 1 | C10: -52 | D10: 1.0004 | F10: 1 | G10: -52 | H10: 1.0004 | J10: =F10*1.5/1.8 -> 0.83333333 | K10: -43 | L10: 0.8276
A11: Q4 | B11: -8.2 | C11: -1354 | D11: -8.19727 | F11: -8.2 | G11: -1354 | H11: -8.19727 | J11: =F11*1.5/1.8 -> -6.8333333 | K11: -1129 | L11: -6.8334
A12: S1 | B12: 0.419 | C12: -60 | D12: 0.41915 | F12: 0.419 | G12: -60 | H12: 0.41915 | J12: =F12*1.5/1.8 -> 0.34916667 | K12: -50 | L12: 0.348
A13: CM1 | C13: 334
A14: CM2 | C14: 304
A15: S2 | B15: -1.141 | C15: -153 | D15: -1.14243 | F15: -1.141 | G15: -153 | H15: -1.14243 | J15: =F15*1.5/1.8 -> -0.95083333 | K15: -127 | L15: -0.9514
A16: Q5 | B16: -7.201 | C16: -853 | D16: -7.2005 | F16: -7.201 | G16: -853 | H16: -7.2005 | J16: =F16*1.5/1.8 -> -6.0008333 | K16: -710 | L16: -6.0049
A17: Q6 | B17: 8.1 | C17: -1011 | D17: 8.0973 | F17: 8.1 | G17: -1011 | H17: 8.0973 | J17: =F17*1.5/1.8 -> 6.75 | K17: -840 | L17: 6.7508
A18: D3 | B18: 12.696259 | C18: -378 | D18: 12.4674 | F18: 12.696259 | G18: -378 | H18: 12.4674 | J18: =F18*1.5/1.8 -> 10.580216 | K18: -316 | L18: 10.56922
A19: Q7 | B19: -4.510638 | C19: -777 | D19: -4.50815 | F19: -4.510638 | G19: -777 | H19: -4.50815 | J19: =F19*1.5/1.8 -> -3.758865 | K19: -643 | L19: -3.7604
A20: O2 | B20: 0.35 | C20: -39 | D20: 0.34754 | F20: 0.35 | G20: -39 | H20: 0.34754 | J20: =F20*1.5/1.8 -> 0.29166667 | K20: -33 | L20: 0.2944
A21: S3 | B21: -1.05 | C21: -154 | D21: -1.04936 | F21: -1.05 | G21: -154 | H21: -1.04936 | J21: =F21*1.5/1.8 -> -0.875 | K21: -129 | L21: -0.8784
A22: CM3 | C22: 306
A23: CM4 | C23: 306
A24: S4 | B24: 0.24 | C24: -35 | D24: 0.242 | F24: 0.24 | G24: -35 | H24: 0.242 | J24: =F24*1.5/1.8 -> 0.2 | K24: -29 | L24: 0.2012
A25: Q8 | B25: -7.9605 | C25: -1062 | D25: -7.95713 | F25: -7.9605 | G25: -1062 | H25: -7.95713 | J25: =F25*1.5/1.8 -> -6.63375 | K25: -882 | L25: -6.632
A26: O3 | B26: 0.85 | C26: -97 | D26: 0.86045 | F26: 0.85 | G26: -97 | H26: 0.86045 | J26: =F26*1.5/1.8 -> 0.70833333 | K26: -80 | L26: -0.71
A27: Q9 | B27: 9.8799 | C27: -1345 | D27: 9.87903 | F27: 9.8799 | G27: -1345 | H27: 9.87903 | J27: =F27*1.5/1.8 -> 8.23325 | K27: -1095 | L27: 8.23459
A29: Q10 | B29: 9.601 | C29: -1325 | D29: 9.60077 | F29: 9.6202 | G29: -1329 | H29: 9.6229 | J29: =F29*1.5/1.8 -> 8.0168333 | K29: -1075 | L29: 8.01383
A30: Q11 | B30: -7.358 | C30: -1000 | D30: -7.35774 | F30: -7.4609 | G30: -1015 | H30: -7.4613 | J30: =F30*1.5/1.8 -> -6.2174167 | K30: -846 | L30: -6.21949
A31: D4 | B31: 15.01022 | C31: -5600 | D31: 15.03837 | F31: 15.01022 | G31: -5600 | H31: 15.03837 | J31: =F31*1.5/1.8 -> 12.508517 | K31: -5234 | L31: 12.50892
A32: D4S | C32: -386 | G32: -386 | K32: 0
A33: Q12 | B33: 7.875 | C33: -1066 | D33: 7.87512 | F33: 7.8697 | G33: -1065 | H33: 7.8683 | J33: =F33*1.5/1.8 -> 6.5580833 | K33: -883 | L33: 6.55561
A34: Q13 | B34: -6.578 | C34: -888 | D34: -6.57767 | F34: -6.4937 | G34: -877 | H34: 6.4955 | J34: =F34*1.5/1.8 -> -5.4114167 | K34: -732 | L34: -5.41307

Sheet 電流表
A1: 要素名 | B1: 型式 | C1: 磁場強度 | D1: 電流 | E1: 電圧 | F1: 電力 | G1: 差圧 | H1: 流量 | I1: 温度上昇 | J1: at-poleからのファクター | K1: 参照電流[A] | M1: 参照磁場強度[G] | O1: 参照差圧[kg/cm2] | Q1: 参照流量[l/min]
C2: [kG] | D2: [A] | E2: [V] | F2: [kW] | G2: [kg/cm2] | H2: [l/min] | I2: [K] | K2: #1 | L2: #2 | M2: #1 | N2: #2 | O2: #1 | P2: #2 | Q2: #1 | R2: #2
A3: K1.8D1 | B3: 5C216SMIC | C3: 11.84605 | D3: =SIGN(C3)*((L3-K3)/(N3-M3)*(ABS(C3)*1000-M3)+K3) -> 730.00745 | E3: ='電圧データ'!$D3/'電圧データ'!$C3*$D3 -> 57.366419 | F3: =D3*E3/1000 -> 41.877913 | G3: 9 | H3: =(R3-Q3)/(P3-O3)*(G3-O3)+Q3 -> 114.63946 | I3: =F3/(H3/60)/4.1855 -> 5.2366649 | J3: 1 | K3: {=INDEX('磁場データ'!$C$2:$AB$2,MATCH(ABS($C3)*1000,'磁場データ'!$C3:$AB3,1))} -> 700 | L3: {=INDEX('磁場データ'!$C$2:$AB$2,MATCH(ABS($C3)*1000,'磁場データ'!$C3:$AB3,1)+1)} -> 800 | M3: {=INDEX('磁場データ'!$C3:$AB3,MATCH(ABS($C3)*1000,'磁場データ'!$C3:$AB3,1))} -> 11568.646 | N3: {=INDEX('磁場データ'!$C3:$AB3,MATCH(ABS($C3)*1000,'磁場データ'!$C3:$AB3,1)+1)} -> 12493.096 | O3: {=INDEX('流量データ'!$C$2:$M$2,MATCH($G3,'流量データ'!$C$2:$M$2,1))} -> 9 | P3: {=INDEX('流量データ'!$C$2:$M$2,MATCH($G3,'流量データ'!$C$2:$M$2,1)+1)} -> 10 | Q3: {=INDEX('流量データ'!$C3:$M3,MATCH($G3,'流量データ'!$C$2:$M$2,1))} -> 114.63946 | R3: {=INDEX('流量データ'!$C3:$M3,MATCH($G3,'流量データ'!$C$2:$M$2,1)+1)} -> 121.75345
A4: K1.8Q1 | B4: NQ312MIC | C4: 4.5833333 | D4: =SIGN(C4)*((L4-K4)/(N4-M4)*(ABS(C4)*1000/2-M4)+K4) -> 533.92317 | E4: ='電圧データ'!$D4/'電圧データ'!$C4*$D4 -> 31.052082 | F4: =D4*E4/1000 -> 16.579426 | G4: 9 | H4: =(R4-Q4)/(P4-O4)*(G4-O4)+Q4 -> 121 | I4: =F4/(H4/60)/4.1855 -> 1.9642104 | J4: 0.5 | K4: {=INDEX('磁場データ'!$C$2:$AB$2,MATCH(ABS($C4)*1000/2,'磁場データ'!$C4:$AB4,1))} -> 500 | L4: {=INDEX('磁場データ'!$C$2:$AB$2,MATCH(ABS($C4)*1000/2,'磁場データ'!$C4:$AB4,1)+1)} -> 600 | M4: {=INDEX('磁場データ'!$C4:$AB4,MATCH(ABS($C4)*1000/2,'磁場データ'!$C4:$AB4,1))} -> 2148.4075 | N4: {=INDEX('磁場データ'!$C4:$AB4,MATCH(ABS($C4)*1000/2,'磁場データ'!$C4:$AB4,1)+1)} -> 2570.7123 | O4: {=INDEX('流量データ'!$C$2:$M$2,MATCH($G4,'流量データ'!$C$2:$M$2,1))} -> 9 | P4: {=INDEX('流量データ'!$C$2:$M$2,MATCH($G4,'流量データ'!$C$2:$M$2,1)+1)} -> 10 | Q4: {=INDEX('流量データ'!$C4:$M4,MATCH($G4,'流量データ'!$C$2:$M$2,1))} -> 121 | R4: {=INDEX('流量データ'!$C4:$M4,MATCH($G4,'流量データ'!$C$2:$M$2,1)+1)} -> 128
A5: K1.8Q2 | B5: Q416MIC | C5: -5.7741667 | D5: =SIGN(C5)*((L5-K5)/(N5-M5)*(ABS(C5)*1000/2-M5)+K5) -> -995.6203 | E5: ='電圧データ'!$D5/'電圧データ'!$C5*$D5 -> -26.492157 | F5: =D5*E5/1000 -> 26.37613 | G5: 10 | H5: =(R5-Q5)/(P5-O5)*(G5-O5)+Q5 -> 41 | I5: =F5/(H5/60)/4.1855 -> 9.2221274 | J5: 0.5 | K5: {=INDEX('磁場データ'!$C$2:$AB$2,MATCH(ABS($C5)*1000/2,'磁場データ'!$C5:$AB5,1))} -> 900 | L5: {=INDEX('磁場データ'!$C$2:$AB$2,MATCH(ABS($C5)*1000/2,'磁場データ'!$C5:$AB5,1)+1)} -> 1000 | M5: {=INDEX('磁場データ'!$C5:$AB5,MATCH(ABS($C5)*1000/2,'磁場データ'!$C5:$AB5,1))} -> 2611.0532 | N5: {=INDEX('磁場データ'!$C5:$AB5,MATCH(ABS($C5)*1000/2,'磁場データ'!$C5:$AB5,1)+1)} -> 2899.7264 | O5: {=INDEX('流量データ'!$C$2:$M$2,MATCH($G5,'流量データ'!$C$2:$M$2,1))} -> 10 | P5: {=INDEX('流量データ'!$C$2:$M$2,MATCH($G5,'流量データ'!$C$2:$M$2,1)+1)} -> 11 | Q5: {=INDEX('流量データ'!$C5:$M5,MATCH($G5,'流量データ'!$C$2:$M$2,1))} -> 41 | R5: {=INDEX('流量データ'!$C5:$M5,MATCH($G5,'流量データ'!$C$2:$M$2,1)+1)} -> 43
A6: K1.8D2 | B6: 8D218SMIC | C6: 15.77386 | D6: =SIGN(C6)*((L6-K6)/(N6-M6)*(ABS(C6)*1000-M6)+K6) -> 1308.9248 | E6: ='電圧データ'!$D6/'電圧データ'!$C6*$D6 -> 86.218305 | F6: =D6*E6/1000 -> 112.85328 | G6: 10 | H6: =(R6-Q6)/(P6-O6)*(G6-O6)+Q6 -> 125 | I6: =F6/(H6/60)/4.1855 -> 12.942199 | J6: 1 | K6: {=INDEX('磁場データ'!$C$2:$AB$2,MATCH(ABS($C6)*1000,'磁場データ'!$C6:$AB6,1))} -> 1300 | L6: {=INDEX('磁場データ'!$C$2:$AB$2,MATCH(ABS($C6)*1000,'磁場データ'!$C6:$AB6,1)+1)} -> 1400 | M6: {=INDEX('磁場データ'!$C6:$AB6,MATCH(ABS($C6)*1000,'磁場データ'!$C6:$AB6,1))} -> 15692.49 | N6: {=INDEX('磁場データ'!$C6:$AB6,MATCH(ABS($C6)*1000,'磁場データ'!$C6:$AB6,1)+1)} -> 16604.222 | O6: {=INDEX('流量データ'!$C$2:$M$2,MATCH($G6,'流量データ'!$C$2:$M$2,1))} -> 10 | P6: {=INDEX('流量データ'!$C$2:$M$2,MATCH($G6,'流量データ'!$C$2:$M$2,1)+1)} -> 11 | Q6: {=INDEX('流量データ'!$C6:$M6,MATCH($G6,'流量データ'!$C$2:$M$2,1))} -> 125 | R6: {=INDEX('流量データ'!$C6:$M6,MATCH($G6,'流量データ'!$C$2:$M$2,1)+1)} -> 132
A7: K1.8Q3 | B7: Q410 | C7: 6.1666667 | D7: =SIGN(C7)*((L7-K7)/(N7-M7)*(ABS(C7)*1000/2-M7)+K7) -> 1018.262 | E7: ='電圧データ'!$D7/'電圧データ'!$C7*$D7 -> 48.321163 | F7: =D7*E7/1000 -> 49.203606 | G7: 5.5 | H7: =(R7-Q7)/(P7-O7)*(G7-O7)+Q7 -> 69 | I7: =F7/(H7/60)/4.1855 -> 10.222374 | J7: 0.5 | K7: {=INDEX('磁場データ'!$C$2:$AB$2,MATCH(ABS($C7)*1000/2,'磁場データ'!$C7:$AB7,1))} -> 1000 | L7: {=INDEX('磁場データ'!$C$2:$AB$2,MATCH(ABS($C7)*1000/2,'磁場データ'!$C7:$AB7,1)+1)} -> 1100 | M7: {=INDEX('磁場データ'!$C7:$AB7,MATCH(ABS($C7)*1000/2,'磁場データ'!$C7:$AB7,1))} -> 3028.0094 | N7: {=INDEX('磁場データ'!$C7:$AB7,MATCH(ABS($C7)*1000/2,'磁場データ'!$C7:$AB7,1)+1)} -> 3330.9542 | O7: {=INDEX('流量データ'!$C$2:$M$2,MATCH($G7,'流量データ'!$C$2:$M$2,1))} -> 5 | P7: {=INDEX('流量データ'!$C$2:$M$2,MATCH($G7,'流量データ'!$C$2:$M$2,1)+1)} -> 6 | Q7: {=INDEX('流量データ'!$C7:$M7,MATCH($G7,'流量データ'!$C$2:$M$2,1))} -> 65 | R7: {=INDEX('流量データ'!$C7:$M7,MATCH($G7,'流量データ'!$C$2:$M$2,1)+1)} -> 73
A8: K1.8O1 | B8: O503 | C8: 0.83333333 | D8: =SIGN(C8)*((L8-K8)/(N8-M8)*(ABS(C8)*1000/8-M8)+K8) -> 43.298611 | E8: ='電圧データ'!$D8/'電圧データ'!$C8*$D8 -> 7.8283889 | F8: =D8*E8/1000 -> 0.33895837 | G8: 5.5 | H8: =(R8-Q8)/(P8-O8)*(G8-O8)+Q8 -> 1.925 | I8: =F8/(H8/60)/4.1855 -> 2.5241754 | J8: 0.125 | K8: {=INDEX('磁場データ'!$C$2:$AB$2,MATCH(ABS($C8)*1000/8,'磁場データ'!$C8:$AB8,1))} -> 0 | L8: {=INDEX('磁場データ'!$C$2:$AB$2,MATCH(ABS($C8)*1000/8,'磁場データ'!$C8:$AB8,1)+1)} -> 100 | M8: {=INDEX('磁場データ'!$C8:$AB8,MATCH(ABS($C8)*1000/8,'磁場データ'!$C8:$AB8,1))} -> 0.25 | N8: {=INDEX('磁場データ'!$C8:$AB8,MATCH(ABS($C8)*1000/8,'磁場データ'!$C8:$AB8,1)+1)} -> 240.25 | O8: {=INDEX('流量データ'!$C$2:$M$2,MATCH($G8,'流量データ'!$C$2:$M$2,1))} -> 5 | P8: {=INDEX('流量データ'!$C$2:$M$2,MATCH($G8,'流量データ'!$C$2:$M$2,1)+1)} -> 6 | Q8: {=INDEX('流量データ'!$C8:$M8,MATCH($G8,'流量データ'!$C$2:$M$2,1))} -> 3.85 | R8: {=INDEX('流量データ'!$C8:$M8,MATCH($G8,'流量データ'!$C$2:$M$2,1)+1)}
A9: K1.8Q4 | B9: Q410 | C9: -6.8333333 | D9: =SIGN(C9)*((L9-K9)/(N9-M9)*(ABS(C9)*1000/2-M9)+K9) -> -1128.9892 | E9: ='電圧データ'!$D9/'電圧データ'!$C9*$D9 -> -53.473033 | F9: =D9*E9/1000 -> 60.370475 | G9: 5.5 | H9: =(R9-Q9)/(P9-O9)*(G9-O9)+Q9 -> 69 | I9: =F9/(H9/60)/4.1855 -> 12.542364 | J9: 0.5 | K9: {=INDEX('磁場データ'!$C$2:$AB$2,MATCH(ABS($C9)*1000/2,'磁場データ'!$C9:$AB9,1))} -> 1100 | L9: {=INDEX('磁場データ'!$C$2:$AB$2,MATCH(ABS($C9)*1000/2,'磁場データ'!$C9:$AB9,1)+1)} -> 1200 | M9: {=INDEX('磁場データ'!$C9:$AB9,MATCH(ABS($C9)*1000/2,'磁場データ'!$C9:$AB9,1))} -> 3329.0465 | N9: {=INDEX('磁場データ'!$C9:$AB9,MATCH(ABS($C9)*1000/2,'磁場データ'!$C9:$AB9,1)+1)} -> 3631.2978 | O9: {=INDEX('流量データ'!$C$2:$M$2,MATCH($G9,'流量データ'!$C$2:$M$2,1))} -> 5 | P9: {=INDEX('流量データ'!$C$2:$M$2,MATCH($G9,'流量データ'!$C$2:$M$2,1)+1)} -> 6 | Q9: {=INDEX('流量データ'!$C9:$M9,MATCH($G9,'流量データ'!$C$2:$M$2,1))} -> 65 | R9: {=INDEX('流量データ'!$C9:$M9,MATCH($G9,'流量データ'!$C$2:$M$2,1)+1)} -> 73
A10: K1.8S1 | B10: SX504 | C10: 0.34916667 | D10: =SIGN(C10)*((L10-K10)/(N10-M10)*(ABS(C10)*1000/4-M10)+K10) -> 50.164718 | E10: ='電圧データ'!$D10/'電圧データ'!$C10*$D10 -> 1.5149745 | F10: =D10*E10/1000 -> 0.075998268 | G10: 5.5 | H10: =(R10-Q10)/(P10-O10)*(G10-O10)+Q10 -> 6 | I10: =F10/(H10/60)/4.1855 -> 0.18157512 | J10: 0.25 | K10: {=INDEX('磁場データ'!$C$2:$AB$2,MATCH(ABS($C10)*1000/4,'磁場データ'!$C10:$AB10,1))} -> 0 | L10: {=INDEX('磁場データ'!$C$2:$AB$2,MATCH(ABS($C10)*1000/4,'磁場データ'!$C10:$AB10,1)+1)} -> 100 | M10: {=INDEX('磁場データ'!$C10:$AB10,MATCH(ABS($C10)*1000/4,'磁場データ'!$C10:$AB10,1))} -> -1.9435079 | N10: {=INDEX('磁場データ'!$C10:$AB10,MATCH(ABS($C10)*1000/4,'磁場データ'!$C10:$AB10,1)+1)} -> 175.94083 | O10: {=INDEX('流量データ'!$C$2:$M$2,MATCH($G10,'流量データ'!$C$2:$M$2,1))} -> 5 | P10: {=INDEX('流量データ'!$C$2:$M$2,MATCH($G10,'流量データ'!$C$2:$M$2,1)+1)} -> 6 | Q10: {=INDEX('流量データ'!$C10:$M10,MATCH($G10,'流量データ'!$C$2:$M$2,1))} -> 12 | R10: {=INDEX('流量データ'!$C10:$M10,MATCH($G10,'流量データ'!$C$2:$M$2,1)+1)}
A11: K1.8CM1 | B11: 4D604V | C11: 4.1788856 | D11: =SIGN(C11)*((L11-K11)/(N11-M11)*(ABS(C11)*1000-M11)+K11) -> 1157.9112 | E11: ='電圧データ'!$D11/'電圧データ'!$C11*$D11 -> 46.412143 | F11: =D11*E11/1000 -> 53.74114 | G11: 5.5 | H11: =(R11-Q11)/(P11-O11)*(G11-O11)+Q11 -> 20.5 | I11: =F11/(H11/60)/4.1855 -> 37.580012 | J11: 1 | K11: {=INDEX('磁場データ'!$C$2:$AB$2,MATCH(ABS($C11)*1000,'磁場データ'!$C11:$AB11,1))} -> 1100 | L11: {=INDEX('磁場データ'!$C$2:$AB$2,MATCH(ABS($C11)*1000,'磁場データ'!$C11:$AB11,1)+1)} -> 1200 | M11: {=INDEX('磁場データ'!$C11:$AB11,MATCH(ABS($C11)*1000,'磁場データ'!$C11:$AB11,1))} -> 4026 | N11: {=INDEX('磁場データ'!$C11:$AB11,MATCH(ABS($C11)*1000,'磁場データ'!$C11:$AB11,1)+1)} -> 4290 | O11: {=INDEX('流量データ'!$C$2:$M$2,MATCH($G11,'流量データ'!$C$2:$M$2,1))} -> 5 | P11: {=INDEX('流量データ'!$C$2:$M$2,MATCH($G11,'流量データ'!$C$2:$M$2,1)+1)} -> 6 | Q11: {=INDEX('流量データ'!$C11:$M11,MATCH($G11,'流量データ'!$C$2:$M$2,1))} -> 19 | R11: {=INDEX('流量データ'!$C11:$M11,MATCH($G11,'流量データ'!$C$2:$M$2,1)+1)} -> 22
A12: K1.8CM2 | B12: 4D604V | C12: 4.1788856 | D12: =SIGN(C12)*((L12-K12)/(N12-M12)*(ABS(C12)*1000-M12)+K12) -> 1163.8348 | E12: ='電圧データ'!$D12/'電圧データ'!$C12*$D12 -> 46.553392 | F12: =D12*E12/1000 -> 54.180459 | G12: 10 | H12: =(R12-Q12)/(P12-O12)*(G12-O12)+Q12 -> 30 | I12: =F12/(H12/60)/4.1855 -> 25.889599 | J12: 1 | K12: {=INDEX('磁場データ'!$C$2:$AB$2,MATCH(ABS($C12)*1000,'磁場データ'!$C12:$AB12,1))} -> 1100 | L12: {=INDEX('磁場データ'!$C$2:$AB$2,MATCH(ABS($C12)*1000,'磁場データ'!$C12:$AB12,1)+1)} -> 1200 | M12: {=INDEX('磁場データ'!$C12:$AB12,MATCH(ABS($C12)*1000,'磁場データ'!$C12:$AB12,1))} -> 4011 | N12: {=INDEX('磁場データ'!$C12:$AB12,MATCH(ABS($C12)*1000,'磁場データ'!$C12:$AB12,1)+1)} -> 4274 | O12: {=INDEX('流量データ'!$C$2:$M$2,MATCH($G12,'流量データ'!$C$2:$M$2,1))} -> 10 | P12: {=INDEX('流量データ'!$C$2:$M$2,MATCH($G12,'流量データ'!$C$2:$M$2,1)+1)} -> 11 | Q12: {=INDEX('流量データ'!$C12:$M12,MATCH($G12,'流量データ'!$C$2:$M$2,1))} -> 30 | R12: {=INDEX('流量データ'!$C12:$M12,MATCH($G12,'流量データ'!$C$2:$M$2,1)+1)} -> 32
A13: K1.8S2 | B13: SX504 | C13: -0.95083333 | D13: =SIGN(C13)*((L13-K13)/(N13-M13)*(ABS(C13)*1000/4-M13)+K13) -> -126.92308 | E13: ='電圧データ'!$D13/'電圧データ'!$C13*$D13 -> -4.0615386 | F13: =D13*E13/1000 -> 0.515503 | G13: 10 | H13: =(R13-Q13)/(P13-O13)*(G13-O13)+Q13 -> 15 | I13: =F13/(H13/60)/4.1855 -> 0.49265608 | J13: 0.25 | K13: {=INDEX('磁場データ'!$C$2:$AB$2,MATCH(ABS($C13)*1000/4,'磁場データ'!$C13:$AB13,1))} -> 100 | L13: {=INDEX('磁場データ'!$C$2:$AB$2,MATCH(ABS($C13)*1000/4,'磁場データ'!$C13:$AB13,1)+1)} -> 200 | M13: {=INDEX('磁場データ'!$C13:$AB13,MATCH(ABS($C13)*1000/4,'磁場データ'!$C13:$AB13,1))} -> 188.25488 | N13: {=INDEX('磁場データ'!$C13:$AB13,MATCH(ABS($C13)*1000/4,'磁場データ'!$C13:$AB13,1)+1)} -> 371.93911 | O13: {=INDEX('流量データ'!$C$2:$M$2,MATCH($G13,'流量データ'!$C$2:$M$2,1))} -> 10 | P13: {=INDEX('流量データ'!$C$2:$M$2,MATCH($G13,'流量データ'!$C$2:$M$2,1)+1)} -> 11 | Q13: {=INDEX('流量データ'!$C13:$M13,MATCH($G13,'流量データ'!$C$2:$M$2,1))} -> 15 | R13: {=INDEX('流量データ'!$C13:$M13,MATCH($G13,'流量データ'!$C$2:$M$2,1)+1)} -> 16
A14: K1.8Q5 | B14: NQ510 | C14: -6.0008333 | D14: =SIGN(C14)*((L14-K14)/(N14-M14)*(ABS(C14)*1000/2-M14)+K14) -> -709.51782 | E14: ='電圧データ'!$D14/'電圧データ'!$C14*$D14 -> -39.07416 | F14: =D14*E14/1000 -> 27.723813 | G14: 10 | H14: =(R14-Q14)/(P14-O14)*(G14-O14)+Q14 -> 92 | I14: =F14/(H14/60)/4.1855 -> 4.3198537 | J14: 0.5 | K14: {=INDEX('磁場データ'!$C$2:$AB$2,MATCH(ABS($C14)*1000/2,'磁場データ'!$C14:$AB14,1))} -> 700 | L14: {=INDEX('磁場データ'!$C$2:$AB$2,MATCH(ABS($C14)*1000/2,'磁場データ'!$C14:$AB14,1)+1)} -> 800 | M14: {=INDEX('磁場データ'!$C14:$AB14,MATCH(ABS($C14)*1000/2,'磁場データ'!$C14:$AB14,1))} -> 2960.5109 | N14: {=INDEX('磁場データ'!$C14:$AB14,MATCH(ABS($C14)*1000/2,'磁場データ'!$C14:$AB14,1)+1)} -> 3379.7853 | O14: {=INDEX('流量データ'!$C$2:$M$2,MATCH($G14,'流量データ'!$C$2:$M$2,1))} -> 10 | P14: {=INDEX('流量データ'!$C$2:$M$2,MATCH($G14,'流量データ'!$C$2:$M$2,1)+1)} -> 11 | Q14: {=INDEX('流量データ'!$C14:$M14,MATCH($G14,'流量データ'!$C$2:$M$2,1))} -> 92 | R14: {=INDEX('流量データ'!$C14:$M14,MATCH($G14,'流量データ'!$C$2:$M$2,1)+1)}
A15: K1.8Q6 | B15: NQ610 | C15: 6.75 | D15: =SIGN(C15)*((L15-K15)/(N15-M15)*(ABS(C15)*1000*$J15-M15)+K15) -> 839.89739 | E15: ='電圧データ'!$D15/'電圧データ'!$C15*$D15 -> 50.146815 | F15: =D15*E15/1000 -> 42.118179 | G15: 10 | H15: =(R15-Q15)/(P15-O15)*(G15-O15)+Q15 -> 103 | I15: =F15/(H15/60)/4.1855 -> 5.8618711 | J15: =80/150 -> 0.53333333 | K15: {=INDEX('磁場データ'!$C$2:$AB$2,MATCH(ABS($C15)*1000*$J15,'磁場データ'!$C15:$AB15,1))} -> 800 | L15: {=INDEX('磁場データ'!$C$2:$AB$2,MATCH(ABS($C15)*1000*$J15,'磁場データ'!$C15:$AB15,1)+1)} -> 900 | M15: {=INDEX('磁場データ'!$C15:$AB15,MATCH(ABS($C15)*1000*$J15,'磁場データ'!$C15:$AB15,1))} -> 3431.05 | N15: {=INDEX('磁場データ'!$C15:$AB15,MATCH(ABS($C15)*1000*$J15,'磁場データ'!$C15:$AB15,1)+1)} -> 3854.5113 | O15: {=INDEX('流量データ'!$C$2:$M$2,MATCH($G15,'流量データ'!$C$2:$M$2,1))} -> 10 | P15: {=INDEX('流量データ'!$C$2:$M$2,MATCH($G15,'流量データ'!$C$2:$M$2,1)+1)} -> 11 | Q15: {=INDEX('流量データ'!$C15:$M15,MATCH($G15,'流量データ'!$C$2:$M$2,1))} -> 103 | R15: {=INDEX('流量データ'!$C15:$M15,MATCH($G15,'流量データ'!$C$2:$M$2,1)+1)} -> 108
A16: K1.8D3 | B16: 6D330S | C16: 12.696259 | D16: =SIGN(C16)*((L16-K16)/(N16-M16)*(ABS(C16)*1000-M16)+K16) -> 383.2351 | E16: ='電圧データ'!$D16/'電圧データ'!$C16*$D16 -> 100.94412 | F16: =D16*E16/1000 -> 38.685331 | G16: 10 | H16: =(R16-Q16)/(P16-O16)*(G16-O16)+Q16 -> 103 | I16: =F16/(H16/60)/4.1855 -> 5.3840986 | J16: 1 | K16: {=INDEX('磁場データ'!$C$2:$AB$2,MATCH(ABS($C16)*1000,'磁場データ'!$C16:$AB16,1))} -> 300 | L16: {=INDEX('磁場データ'!$C$2:$AB$2,MATCH(ABS($C16)*1000,'磁場データ'!$C16:$AB16,1)+1)} -> 400 | M16: {=INDEX('磁場データ'!$C16:$AB16,MATCH(ABS($C16)*1000,'磁場データ'!$C16:$AB16,1))} -> 10063.051 | N16: {=INDEX('磁場データ'!$C16:$AB16,MATCH(ABS($C16)*1000,'磁場データ'!$C16:$AB16,1)+1)} -> 13226.63 | O16: {=INDEX('流量データ'!$C$2:$M$2,MATCH($G16,'流量データ'!$C$2:$M$2,1))} -> 10 | P16: {=INDEX('流量データ'!$C$2:$M$2,MATCH($G16,'流量データ'!$C$2:$M$2,1)+1)} -> 11 | Q16: {=INDEX('流量データ'!$C16:$M16,MATCH($G16,'流量データ'!$C$2:$M$2,1))} -> 103 | R16: {=INDEX('流量データ'!$C16:$M16,MATCH($G16,'流量データ'!$C$2:$M$2,1)+1)} -> 108
A17: K1.8Q7 | B17: NQ408 | C17: -3.758865 | D17: =SIGN(C17)*((L17-K17)/(N17-M17)*(ABS(C17)*1000/2-M17)+K17) -> -642.73037 | E17: ='電圧データ'!$D17/'電圧データ'!$C17*$D17 -> -9.1589078 | F17: =D17*E17/1000 -> 5.8867082 | G17: 10 | H17: =(R17-Q17)/(P17-O17)*(G17-O17)+Q17 -> 75 | I17: =F17/(H17/60)/4.1855 -> 1.1251622 | J17: 0.5 | K17: {=INDEX('磁場データ'!$C$2:$AB$2,MATCH(ABS($C17)*1000/2,'磁場データ'!$C17:$AB17,1))} -> 600 | L17: {=INDEX('磁場データ'!$C$2:$AB$2,MATCH(ABS($C17)*1000/2,'磁場データ'!$C17:$AB17,1)+1)} -> 700 | M17: {=INDEX('磁場データ'!$C17:$AB17,MATCH(ABS($C17)*1000/2,'磁場データ'!$C17:$AB17,1))} -> 1758.45 | N17: {=INDEX('磁場データ'!$C17:$AB17,MATCH(ABS($C17)*1000/2,'磁場データ'!$C17:$AB17,1)+1)} -> 2041.58 | O17: {=INDEX('流量データ'!$C$2:$M$2,MATCH($G17,'流量データ'!$C$2:$M$2,1))} -> 10 | P17: {=INDEX('流量データ'!$C$2:$M$2,MATCH($G17,'流量データ'!$C$2:$M$2,1)+1)} -> 11 | Q17: {=INDEX('流量データ'!$C17:$M17,MATCH($G17,'流量データ'!$C$2:$M$2,1))} -> 75 | R17: {=INDEX('流量データ'!$C17:$M17,MATCH($G17,'流量データ'!$C$2:$M$2,1)+1)} -> 83
A18: K1.8O2 | B18: O603 | C18: 0.29166667 | D18: =SIGN(C18)*((L18-K18)/(N18-M18)*(ABS(C18)*1000/8-M18)+K18) -> 32.693755 | E18: ='電圧データ'!$D18/'電圧データ'!$C18*$D18 -> 1.706614 | F18: =D18*E18/1000 -> 0.055795619 | G18: 10 | H18: =(R18-Q18)/(P18-O18)*(G18-O18)+Q18 -> 10.5 | I18: =F18/(H18/60)/4.1855 -> 0.076175394 | J18: 0.125 | K18: {=INDEX('磁場データ'!$C$2:$AB$2,MATCH(ABS($C18)*1000/8,'磁場データ'!$C18:$AB18,1))} -> 0 | L18: {=INDEX('磁場データ'!$C$2:$AB$2,MATCH(ABS($C18)*1000/8,'磁場データ'!$C18:$AB18,1)+1)} -> 100 | M18: {=INDEX('磁場データ'!$C18:$AB18,MATCH(ABS($C18)*1000/8,'磁場データ'!$C18:$AB18,1))} -> 0.25 | N18: {=INDEX('磁場データ'!$C18:$AB18,MATCH(ABS($C18)*1000/8,'磁場データ'!$C18:$AB18,1)+1)} -> 111 | O18: {=INDEX('流量データ'!$C$2:$M$2,MATCH($G18,'流量データ'!$C$2:$M$2,1))} -> 10 | P18: {=INDEX('流量データ'!$C$2:$M$2,MATCH($G18,'流量データ'!$C$2:$M$2,1)+1)} -> 11 | Q18: {=INDEX('流量データ'!$C18:$M18,MATCH($G18,'流量データ'!$C$2:$M$2,1))} -> 10.5 | R18: {=INDEX('流量データ'!$C18:$M18,MATCH($G18,'流量データ'!$C$2:$M$2,1)+1)}
A19: K1.8S3 | B19: SX604 | C19: -0.875 | D19: =SIGN(C19)*((L19-K19)/(N19-M19)*(ABS(C19)*1000/4-M19)+K19) -> -128.50877 | E19: ='電圧データ'!$D19/'電圧データ'!$C19*$D19 -> -4.4264133 | F19: =D19*E19/1000 -> 0.56883293 | G19: 10 | H19: =(R19-Q19)/(P19-O19)*(G19-O19)+Q19 -> 19.6 | I19: =F19/(H19/60)/4.1855 -> 0.41603758 | J19: 0.25 | K19: {=INDEX('磁場データ'!$C$2:$AB$2,MATCH(ABS($C19)*1000/4,'磁場データ'!$C19:$AB19,1))} -> 100 | L19: {=INDEX('磁場データ'!$C$2:$AB$2,MATCH(ABS($C19)*1000/4,'磁場データ'!$C19:$AB19,1)+1)} -> 200 | M19: {=INDEX('磁場データ'!$C19:$AB19,MATCH(ABS($C19)*1000/4,'磁場データ'!$C19:$AB19,1))} -> 170 | N19: {=INDEX('磁場データ'!$C19:$AB19,MATCH(ABS($C19)*1000/4,'磁場データ'!$C19:$AB19,1)+1)} -> 341 | O19: {=INDEX('流量データ'!$C$2:$M$2,MATCH($G19,'流量データ'!$C$2:$M$2,1))} -> 10 | P19: {=INDEX('流量データ'!$C$2:$M$2,MATCH($G19,'流量データ'!$C$2:$M$2,1)+1)} -> 11 | Q19: {=INDEX('流量データ'!$C19:$M19,MATCH($G19,'流量データ'!$C$2:$M$2,1))} -> 19.6 | R19: {=INDEX('流量データ'!$C19:$M19,MATCH($G19,'流量データ'!$C$2:$M$2,1)+1)}
A20: K1.8CM3 | B20: 4D604V | C20: 4.1788856 | D20: =SIGN(C20)*((L20-K20)/(N20-M20)*(ABS(C20)*1000-M20)+K20) -> 1157.9112 | E20: ='電圧データ'!$D20/'電圧データ'!$C20*$D20 -> 44.785326 | F20: =D20*E20/1000 -> 51.85743 | G20: 10 | H20: =(R20-Q20)/(P20-O20)*(G20-O20)+Q20 -> 32.8 | I20: =F20/(H20/60)/4.1855 -> 22.664234 | J20: 1 | K20: {=INDEX('磁場データ'!$C$2:$AB$2,MATCH(ABS($C20)*1000,'磁場データ'!$C20:$AB20,1))} -> 1100 | L20: {=INDEX('磁場データ'!$C$2:$AB$2,MATCH(ABS($C20)*1000,'磁場データ'!$C20:$AB20,1)+1)} -> 1200 | M20: {=INDEX('磁場データ'!$C20:$AB20,MATCH(ABS($C20)*1000,'磁場データ'!$C20:$AB20,1))} -> 4026 | N20: {=INDEX('磁場データ'!$C20:$AB20,MATCH(ABS($C20)*1000,'磁場データ'!$C20:$AB20,1)+1)} -> 4290 | O20: {=INDEX('流量データ'!$C$2:$M$2,MATCH($G20,'流量データ'!$C$2:$M$2,1))} -> 10 | P20: {=INDEX('流量データ'!$C$2:$M$2,MATCH($G20,'流量データ'!$C$2:$M$2,1)+1)} -> 11 | Q20: {=INDEX('流量データ'!$C20:$M20,MATCH($G20,'流量データ'!$C$2:$M$2,1))} -> 32.8 | R20: {=INDEX('流量データ'!$C20:$M20,MATCH($G20,'流量データ'!$C$2:$M$2,1)+1)}
A21: K1.8CM4 | B21: 4D604V | C21: 4.1788856 | D21: =SIGN(C21)*((L21-K21)/(N21-M21)*(ABS(C21)*1000-M21)+K21) -> 1157.9112 | E21: ='電圧データ'!$D21/'電圧データ'!$C21*$D21 -> 45.072411 | F21: =D21*E21/1000 -> 52.189849 | G21: 10 | H21: =(R21-Q21)/(P21-O21)*(G21-O21)+Q21 -> 33.6 | I21: =F21/(H21/60)/4.1855 -> 22.266434 | J21: 1 | K21: {=INDEX('磁場データ'!$C$2:$AB$2,MATCH(ABS($C21)*1000,'磁場データ'!$C21:$AB21,1))} -> 1100 | L21: {=INDEX('磁場データ'!$C$2:$AB$2,MATCH(ABS($C21)*1000,'磁場データ'!$C21:$AB21,1)+1)} -> 1200 | M21: {=INDEX('磁場データ'!$C21:$AB21,MATCH(ABS($C21)*1000,'磁場データ'!$C21:$AB21,1))} -> 4026 | N21: {=INDEX('磁場データ'!$C21:$AB21,MATCH(ABS($C21)*1000,'磁場データ'!$C21:$AB21,1)+1)} -> 4290 | O21: {=INDEX('流量データ'!$C$2:$M$2,MATCH($G21,'流量データ'!$C$2:$M$2,1))} -> 10 | P21: {=INDEX('流量データ'!$C$2:$M$2,MATCH($G21,'流量データ'!$C$2:$M$2,1)+1)} -> 11 | Q21: {=INDEX('流量データ'!$C21:$M21,MATCH($G21,'流量データ'!$C$2:$M$2,1))} -> 33.6 | R21: {=INDEX('流量データ'!$C21:$M21,MATCH($G21,'流量データ'!$C$2:$M$2,1)+1)}
A22: K1.8S4 | B22: SX604 | C22: 0.2 | D22: =SIGN(C22)*((L22-K22)/(N22-M22)*(ABS(C22)*1000/4-M22)+K22) -> 28.823529 | E22: ='電圧データ'!$D22/'電圧データ'!$C22*$D22 -> 0.99281046 | F22: =D22*E22/1000 -> 0.028616301 | G22: 10 | H22: =(R22-Q22)/(P22-O22)*(G22-O22)+Q22 -> 19.6 | I22: =F22/(H22/60)/4.1855 -> 0.02092962 | J22: 0.25 | K22: {=INDEX('磁場データ'!$C$2:$AB$2,MATCH(ABS($C22)*1000/4,'磁場データ'!$C22:$AB22,1))} -> 0 | L22: {=INDEX('磁場データ'!$C$2:$AB$2,MATCH(ABS($C22)*1000/4,'磁場データ'!$C22:$AB22,1)+1)} -> 100 | M22: {=INDEX('磁場データ'!$C22:$AB22,MATCH(ABS($C22)*1000/4,'磁場データ'!$C22:$AB22,1))} -> 1 | N22: {=INDEX('磁場データ'!$C22:$AB22,MATCH(ABS($C22)*1000/4,'磁場データ'!$C22:$AB22,1)+1)} -> 171 | O22: {=INDEX('流量データ'!$C$2:$M$2,MATCH($G22,'流量データ'!$C$2:$M$2,1))} -> 10 | P22: {=INDEX('流量データ'!$C$2:$M$2,MATCH($G22,'流量データ'!$C$2:$M$2,1)+1)} -> 11 | Q22: {=INDEX('流量データ'!$C22:$M22,MATCH($G22,'流量データ'!$C$2:$M$2,1))} -> 19.6 | R22: {=INDEX('流量データ'!$C22:$M22,MATCH($G22,'流量データ'!$C$2:$M$2,1)+1)}
A23: K1.8Q8 | B23: NQ512 | C23: -6.63375 | D23: =SIGN(C23)*((L23-K23)/(N23-M23)*(ABS(C23)*1000/2-M23)+K23) -> -882.23023 | E23: ='電圧データ'!$D23/'電圧データ'!$C23*$D23 -> -30.701612 | F23: =D23*E23/1000 -> 27.08589 | G23: 10 | H23: =(R23-Q23)/(P23-O23)*(G23-O23)+Q23 -> 158 | I23: =F23/(H23/60)/4.1855 -> 2.4574796 | J23: 0.5 | K23: {=INDEX('磁場データ'!$C$2:$AB$2,MATCH(ABS($C23)*1000/2,'磁場データ'!$C23:$AB23,1))} -> 800 | L23: {=INDEX('磁場データ'!$C$2:$AB$2,MATCH(ABS($C23)*1000/2,'磁場データ'!$C23:$AB23,1)+1)} -> 900 | M23: {=INDEX('磁場データ'!$C23:$AB23,MATCH(ABS($C23)*1000/2,'磁場データ'!$C23:$AB23,1))} -> 3005.28 | N23: {=INDEX('磁場データ'!$C23:$AB23,MATCH(ABS($C23)*1000/2,'磁場データ'!$C23:$AB23,1)+1)} -> 3384.21 | O23: {=INDEX('流量データ'!$C$2:$M$2,MATCH($G23,'流量データ'!$C$2:$M$2,1))} -> 10 | P23: {=INDEX('流量データ'!$C$2:$M$2,MATCH($G23,'流量データ'!$C$2:$M$2,1)+1)} -> 11 | Q23: {=INDEX('流量データ'!$C23:$M23,MATCH($G23,'流量データ'!$C$2:$M$2,1))} -> 158 | R23: {=INDEX('流量データ'!$C23:$M23,MATCH($G23,'流量データ'!$C$2:$M$2,1)+1)}
A24: K1.8O3 | B24: O603 | C24: 0.70833333 | D24: =SIGN(C24)*((L24-K24)/(N24-M24)*(ABS(C24)*1000/8-M24)+K24) -> 79.811676 | E24: ='電圧データ'!$D24/'電圧データ'!$C24*$D24 -> 4.1502072 | F24: =D24*E24/1000 -> 0.33123499 | G24: 10 | H24: =(R24-Q24)/(P24-O24)*(G24-O24)+Q24 -> 10.5 | I24: =F24/(H24/60)/4.1855 -> 0.45222109 | J24: 0.125 | K24: {=INDEX('磁場データ'!$C$2:$AB$2,MATCH(ABS($C24)*1000/8,'磁場データ'!$C24:$AB24,1))} -> 0 | L24: {=INDEX('磁場データ'!$C$2:$AB$2,MATCH(ABS($C24)*1000/8,'磁場データ'!$C24:$AB24,1)+1)} -> 100 | M24: {=INDEX('磁場データ'!$C24:$AB24,MATCH(ABS($C24)*1000/8,'磁場データ'!$C24:$AB24,1))} -> 0.25 | N24: {=INDEX('磁場データ'!$C24:$AB24,MATCH(ABS($C24)*1000/8,'磁場データ'!$C24:$AB24,1)+1)} -> 110.875 | O24: {=INDEX('流量データ'!$C$2:$M$2,MATCH($G24,'流量データ'!$C$2:$M$2,1))} -> 10 | P24: {=INDEX('流量データ'!$C$2:$M$2,MATCH($G24,'流量データ'!$C$2:$M$2,1)+1)} -> 11 | Q24: {=INDEX('流量データ'!$C24:$M24,MATCH($G24,'流量データ'!$C$2:$M$2,1))} -> 10.5 | R24: {=INDEX('流量データ'!$C24:$M24,MATCH($G24,'流量データ'!$C$2:$M$2,1)+1)}
A25: K1.8Q9 | B25: NQ518 | C25: 8.23325 | D25: =SIGN(C25)*((L25-K25)/(N25-M25)*(ABS(C25)*1000/2-M25)+K25) -> 1094.8234 | E25: ='電圧データ'!$D25/'電圧データ'!$C25*$D25 -> 56.930819 | F25: =D25*E25/1000 -> 62.329196 | G25: 10 | H25: =(R25-Q25)/(P25-O25)*(G25-O25)+Q25 -> 128 | I25: =F25/(H25/60)/4.1855 -> 6.9804827 | J25: 0.5 | K25: {=INDEX('磁場データ'!$C$2:$AB$2,MATCH(ABS($C25)*1000/2,'磁場データ'!$C25:$AB25,1))} -> 1000 | L25: {=INDEX('磁場データ'!$C$2:$AB$2,MATCH(ABS($C25)*1000/2,'磁場データ'!$C25:$AB25,1)+1)} -> 1100 | M25: {=INDEX('磁場データ'!$C25:$AB25,MATCH(ABS($C25)*1000/2,'磁場データ'!$C25:$AB25,1))} -> 3757.32 | N25: {=INDEX('磁場データ'!$C25:$AB25,MATCH(ABS($C25)*1000/2,'磁場データ'!$C25:$AB25,1)+1)} -> 4136.24 | O25: {=INDEX('流量データ'!$C$2:$M$2,MATCH($G25,'流量データ'!$C$2:$M$2,1))} -> 10 | P25: {=INDEX('流量データ'!$C$2:$M$2,MATCH($G25,'流量データ'!$C$2:$M$2,1)+1)} -> 11 | Q25: {=INDEX('流量データ'!$C25:$M25,MATCH($G25,'流量データ'!$C$2:$M$2,1))} -> 128 | R25: {=INDEX('流量データ'!$C25:$M25,MATCH($G25,'流量データ'!$C$2:$M$2,1)+1)} -> 136
A26: K1.8Q10 | B26: NQ418 | C26: 8.0168333 | D26: =SIGN(C26)*((L26-K26)/(N26-M26)*(ABS(C26)*1000/2-M26)+K26) -> 1075.4113 | E26: ='電圧データ'!$D26/'電圧データ'!$C26*$D26 -> 36.456442 | F26: =D26*E26/1000 -> 39.205668 | G26: 10 | H26: =(R26-Q26)/(P26-O26)*(G26-O26)+Q26 -> 162 | I26: =F26/(H26/60)/4.1855 -> 3.4692672 | J26: 0.5 | K26: {=INDEX('磁場データ'!$C$2:$AB$2,MATCH(ABS($C26)*1000/2,'磁場データ'!$C26:$AB26,1))} -> 1000 | L26: {=INDEX('磁場データ'!$C$2:$AB$2,MATCH(ABS($C26)*1000/2,'磁場データ'!$C26:$AB26,1)+1)} -> 1100 | M26: {=INDEX('磁場データ'!$C26:$AB26,MATCH(ABS($C26)*1000/2,'磁場データ'!$C26:$AB26,1))} -> 3733.06 | N26: {=INDEX('磁場データ'!$C26:$AB26,MATCH(ABS($C26)*1000/2,'磁場データ'!$C26:$AB26,1)+1)} -> 4098.2 | O26: {=INDEX('流量データ'!$C$2:$M$2,MATCH($G26,'流量データ'!$C$2:$M$2,1))} -> 10 | P26: {=INDEX('流量データ'!$C$2:$M$2,MATCH($G26,'流量データ'!$C$2:$M$2,1)+1)} -> 11 | Q26: {=INDEX('流量データ'!$C26:$M26,MATCH($G26,'流量データ'!$C$2:$M$2,1))} -> 162 | R26: {=INDEX('流量データ'!$C26:$M26,MATCH($G26,'流量データ'!$C$2:$M$2,1)+1)} -> 170
A27: K1.8Q11 | B27: NQ412 | C27: -6.2174167 | D27: =SIGN(C27)*((L27-K27)/(N27-M27)*(ABS(C27)*1000/2-M27)+K27) -> -845.721 | E27: ='電圧データ'!$D27/'電圧データ'!$C27*$D27 -> -22.919039 | F27: =D27*E27/1000 -> 19.383113 | G27: 10 | H27: =(R27-Q27)/(P27-O27)*(G27-O27)+Q27 -> 63 | I27: =F27/(H27/60)/4.1855 -> 4.4104903 | J27: 0.5 | K27: {=INDEX('磁場データ'!$C$2:$AB$2,MATCH(ABS($C27)*1000/2,'磁場データ'!$C27:$AB27,1))} -> 800 | L27: {=INDEX('磁場データ'!$C$2:$AB$2,MATCH(ABS($C27)*1000/2,'磁場データ'!$C27:$AB27,1)+1)} -> 900 | M27: {=INDEX('磁場データ'!$C27:$AB27,MATCH(ABS($C27)*1000/2,'磁場データ'!$C27:$AB27,1))} -> 2939.12 | N27: {=INDEX('磁場データ'!$C27:$AB27,MATCH(ABS($C27)*1000/2,'磁場データ'!$C27:$AB27,1)+1)} -> 3310.04 | O27: {=INDEX('流量データ'!$C$2:$M$2,MATCH($G27,'流量データ'!$C$2:$M$2,1))} -> 10 | P27: {=INDEX('流量データ'!$C$2:$M$2,MATCH($G27,'流量データ'!$C$2:$M$2,1)+1)} -> 11 | Q27: {=INDEX('流量データ'!$C27:$M27,MATCH($G27,'流量データ'!$C$2:$M$2,1))} -> 63 | R27: {=INDEX('流量データ'!$C27:$M27,MATCH($G27,'流量データ'!$C$2:$M$2,1)+1)} -> 66
A28: K1.8D4 | B28: 13D389S | C28: 13 | D28: =SIGN(C28)*((L28-K28)/(N28-M28)*(ABS(C28)*1000-M28)+K28) -> 5440.3361 | E28: ='電圧データ'!$D28/'電圧データ'!$C28*$D28 -> 152.32941 | F28: =D28*E28/1000 -> 828.7232 | G28: 10 | H28: =(R28-Q28)/(P28-O28)*(G28-O28)+Q28 -> 557 | I28: =F28/(H28/60)/4.1855 -> 21.328397 | J28: 1 | K28: {=INDEX('磁場データ'!$C$2:$AB$2,MATCH(ABS($C28)*1000,'磁場データ'!$C28:$AB28,1))*5} -> 5000 | L28: {=INDEX('磁場データ'!$C$2:$AB$2,MATCH(ABS($C28)*1000,'磁場データ'!$C28:$AB28,1)+1)*5} -> 5500 | M28: {=INDEX('磁場データ'!$C28:$AB28,MATCH(ABS($C28)*1000,'磁場データ'!$C28:$AB28,1))} -> 11952 | N28: {=INDEX('磁場データ'!$C28:$AB28,MATCH(ABS($C28)*1000,'磁場データ'!$C28:$AB28,1)+1)} -> 13142 | O28: {=INDEX('流量データ'!$C$2:$M$2,MATCH($G28,'流量データ'!$C$2:$M$2,1))} -> 10 | P28: {=INDEX('流量データ'!$C$2:$M$2,MATCH($G28,'流量データ'!$C$2:$M$2,1)+1)} -> 11 | Q28: {=INDEX('流量データ'!$C28:$M28,MATCH($G28,'流量データ'!$C$2:$M$2,1))} -> 557 | R28: {=INDEX('流量データ'!$C28:$M28,MATCH($G28,'流量データ'!$C$2:$M$2,1)+1)}
A29: K1.8D4副 | B29: 13D389S副 | C29: 3.678 | D29: =SIGN(C29)*((L29-K29)/(N29-M29)*(ABS(C29)*1000-M29)+K29) -> 877.42449 | E29: ='電圧データ'!$D29/'電圧データ'!$C29*$D29 -> 179.52105 | F29: =D29*E29/1000 -> 157.51616 | G29: 10 | H29: =(R29-Q29)/(P29-O29)*(G29-O29)+Q29 -> 117 | I29: =F29/(H29/60)/4.1855 -> 19.299372 | J29: 1 | K29: {=INDEX('磁場データ'!$C$2:$AB$2,MATCH(ABS($C29)*1000,'磁場データ'!$C29:$AB29,1))} -> 800 | L29: {=INDEX('磁場データ'!$C$2:$AB$2,MATCH(ABS($C29)*1000,'磁場データ'!$C29:$AB29,1)+1)} -> 900 | M29: {=INDEX('磁場データ'!$C29:$AB29,MATCH(ABS($C29)*1000,'磁場データ'!$C29:$AB29,1))} -> 3352.9667 | N29: {=INDEX('磁場データ'!$C29:$AB29,MATCH(ABS($C29)*1000,'磁場データ'!$C29:$AB29,1)+1)} -> 3772.7736 | O29: {=INDEX('流量データ'!$C$2:$M$2,MATCH($G29,'流量データ'!$C$2:$M$2,1))} -> 10 | P29: {=INDEX('流量データ'!$C$2:$M$2,MATCH($G29,'流量データ'!$C$2:$M$2,1)+1)} -> 11 | Q29: {=INDEX('流量データ'!$C29:$M29,MATCH($G29,'流量データ'!$C$2:$M$2,1))} -> 117 | R29: {=INDEX('流量データ'!$C29:$M29,MATCH($G29,'流量データ'!$C$2:$M$2,1)+1)}
A30: K1.8Q12 | B30: NQ412 | C30: 6.5580833 | D30: =SIGN(C30)*((L30-K30)/(N30-M30)*(ABS(C30)*1000/2-M30)+K30) -> 883.33333 | E30: ='電圧データ'!$D30/'電圧データ'!$C30*$D30 -> 23.938333 | F30: =D30*E30/1000 -> 21.145528 | G30: 10 | H30: =(R30-Q30)/(P30-O30)*(G30-O30)+Q30 -> 63 | I30: =F30/(H30/60)/4.1855 -> 4.8115154 | J30: 0.5 | K30: {=INDEX('磁場データ'!$C$2:$AB$2,MATCH(ABS($C30)*1000/2,'磁場データ'!$C30:$AB30,1))} -> 800 | L30: {=INDEX('磁場データ'!$C$2:$AB$2,MATCH(ABS($C30)*1000/2,'磁場データ'!$C30:$AB30,1)+1)} -> 900 | M30: {=INDEX('磁場データ'!$C30:$AB30,MATCH(ABS($C30)*1000/2,'磁場データ'!$C30:$AB30,1))} -> 2970 | N30: {=INDEX('磁場データ'!$C30:$AB30,MATCH(ABS($C30)*1000/2,'磁場データ'!$C30:$AB30,1)+1)} -> 3340.85 | O30: {=INDEX('流量データ'!$C$2:$M$2,MATCH($G30,'流量データ'!$C$2:$M$2,1))} -> 10 | P30: {=INDEX('流量データ'!$C$2:$M$2,MATCH($G30,'流量データ'!$C$2:$M$2,1)+1)} -> 11 | Q30: {=INDEX('流量データ'!$C30:$M30,MATCH($G30,'流量データ'!$C$2:$M$2,1))} -> 63 | R30: {=INDEX('流量データ'!$C30:$M30,MATCH($G30,'流量データ'!$C$2:$M$2,1)+1)} -> 66
A31: K1.8Q13 | B31: NQ412 | C31: -5.4114167 | D31: =SIGN(C31)*((L31-K31)/(N31-M31)*(ABS(C31)*1000/2-M31)+K31) -> -731.77851 | E31: ='電圧データ'!$D31/'電圧データ'!$C31*$D31 -> -19.831198 | F31: =D31*E31/1000 -> 14.512044 | G31: 10 | H31: =(R31-Q31)/(P31-O31)*(G31-O31)+Q31 -> 64 | I31: =F31/(H31/60)/4.1855 -> 3.2505176 | J31: 0.5 | K31: {=INDEX('磁場データ'!$C$2:$AB$2,MATCH(ABS($C31)*1000/2,'磁場データ'!$C31:$AB31,1))} -> 700 | L31: {=INDEX('磁場データ'!$C$2:$AB$2,MATCH(ABS($C31)*1000/2,'磁場データ'!$C31:$AB31,1)+1)} -> 800 | M31: {=INDEX('磁場データ'!$C31:$AB31,MATCH(ABS($C31)*1000/2,'磁場データ'!$C31:$AB31,1))} -> 2587.13 | N31: {=INDEX('磁場データ'!$C31:$AB31,MATCH(ABS($C31)*1000/2,'磁場データ'!$C31:$AB31,1)+1)} -> 2960.27 | O31: {=INDEX('流量データ'!$C$2:$M$2,MATCH($G31,'流量データ'!$C$2:$M$2,1))} -> 10 | P31: {=INDEX('流量データ'!$C$2:$M$2,MATCH($G31,'流量データ'!$C$2:$M$2,1)+1)} -> 11 | Q31: {=INDEX('流量データ'!$C31:$M31,MATCH($G31,'流量データ'!$C$2:$M$2,1))} -> 64 | R31: {=INDEX('流量データ'!$C31:$M31,MATCH($G31,'流量データ'!$C$2:$M$2,1)+1)} -> 67
A32: K1.8BRS3 | B32: SX404 | C32: 1.171 | D32: =SIGN(C32)*((L32-K32)/(N32-M32)*(ABS(C32)*1000/4-M32)+K32) -> 39.0625 | E32: ='電圧データ'!$D32/'電圧データ'!$C32*$D32 -> 16.205659 | F32: =D32*E32/1000 -> 0.63303355 | G32: 10 | H32: =(R32-Q32)/(P32-O32)*(G32-O32)+Q32 -> 0 | I32: =F32/(H32/60)/4.1855 -> #DIV/0! | J32: 0.25 | K32: {=INDEX('磁場データ'!$C$2:$AB$2,MATCH(ABS($C32)*1000/4,'磁場データ'!$C32:$AB32,1))/50} -> 38 | L32: {=INDEX('磁場データ'!$C$2:$AB$2,MATCH(ABS($C32)*1000/4,'磁場データ'!$C32:$AB32,1)+1)/50} -> 40 | M32: {=INDEX('磁場データ'!$C32:$AB32,MATCH(ABS($C32)*1000/4,'磁場データ'!$C32:$AB32,1))} -> 288.5 | N32: {=INDEX('磁場データ'!$C32:$AB32,MATCH(ABS($C32)*1000/4,'磁場データ'!$C32:$AB32,1)+1)} -> 296.5 | O32: {=INDEX('流量データ'!$C$2:$M$2,MATCH($G32,'流量データ'!$C$2:$M$2,1))} -> 10 | P32: {=INDEX('流量データ'!$C$2:$M$2,MATCH($G32,'流量データ'!$C$2:$M$2,1)+1)} -> 11 | Q32: {=INDEX('流量データ'!$C32:$M32,MATCH($G32,'流量データ'!$C$2:$M$2,1))} -> 0 | R32: {=INDEX('流量データ'!$C32:$M32,MATCH($G32,'流量データ'!$C$2:$M$2,1)+1)} -> 0
A33: K1.8BRQ7 | B33: Q306 | C33: -4.435 | D33: =SIGN(C33)*((L33-K33)/(N33-M33)*(ABS(C33)*1000/2-M33)+K33) -> -511.11111 | E33: ='電圧データ'!$D33/'電圧データ'!$C33*$D33 -> -21.559596 | F33: =D33*E33/1000 -> 11.019349 | G33: 10 | H33: =(R33-Q33)/(P33-O33)*(G33-O33)+Q33 -> 42.1 | I33: =F33/(H33/60)/4.1855 -> 3.7521289 | J33: 0.5 | K33: {=INDEX('磁場データ'!$C$2:$AB$2,MATCH(ABS($C33)*1000/2,'磁場データ'!$C33:$AB33,1))} -> 500 | L33: {=INDEX('磁場データ'!$C$2:$AB$2,MATCH(ABS($C33)*1000/2,'磁場データ'!$C33:$AB33,1)+1)} -> 600 | M33: {=INDEX('磁場データ'!$C33:$AB33,MATCH(ABS($C33)*1000/2,'磁場データ'!$C33:$AB33,1))} -> 2169.375 | N33: {=INDEX('磁場データ'!$C33:$AB33,MATCH(ABS($C33)*1000/2,'磁場データ'!$C33:$AB33,1)+1)} -> 2602.5 | O33: {=INDEX('流量データ'!$C$2:$M$2,MATCH($G33,'流量データ'!$C$2:$M$2,1))} -> 10 | P33: {=INDEX('流量データ'!$C$2:$M$2,MATCH($G33,'流量データ'!$C$2:$M$2,1)+1)} -> 11 | Q33: {=INDEX('流量データ'!$C33:$M33,MATCH($G33,'流量データ'!$C$2:$M$2,1))} -> 42.1 | R33: {=INDEX('流量データ'!$C33:$M33,MATCH($G33,'流量データ'!$C$2:$M$2,1)+1)}
A34: K1.8BRD4 | B34: 8D440S | C34: 19.32011 | D34: =SIGN(C34)*((L34-K34)/(N34-M34)*(ABS(C34)*1000-M34)+K34) -> 2126.6095 | E34: ='電圧データ'!$D34/'電圧データ'!$C34*$D34 -> 160.55902 | F34: =D34*E34/1000 -> 341.44632 | G34: 10 | H34: =(R34-Q34)/(P34-O34)*(G34-O34)+Q34 -> 180 | I34: =F34/(H34/60)/4.1855 -> 27.192795 | J34: 1 | K34: {=INDEX('磁場データ'!$C$2:$AB$2,MATCH(ABS($C34)*1000,'磁場データ'!$C34:$AB34,1))} -> 2100 | L34: {=INDEX('磁場データ'!$C$2:$AB$2,MATCH(ABS($C34)*1000,'磁場データ'!$C34:$AB34,1)+1)} -> 2200 | M34: {=INDEX('磁場データ'!$C34:$AB34,MATCH(ABS($C34)*1000,'磁場データ'!$C34:$AB34,1))} -> 19129.241 | N34: {=INDEX('磁場データ'!$C34:$AB34,MATCH(ABS($C34)*1000,'磁場データ'!$C34:$AB34,1)+1)} -> 19846.539 | O34: {=INDEX('流量データ'!$C$2:$M$2,MATCH($G34,'流量データ'!$C$2:$M$2,1))} -> 10 | P34: {=INDEX('流量データ'!$C$2:$M$2,MATCH($G34,'流量データ'!$C$2:$M$2,1)+1)} -> 11 | Q34: {=INDEX('流量データ'!$C34:$M34,MATCH($G34,'流量データ'!$C$2:$M$2,1))} -> 180 | R34: {=INDEX('流量データ'!$C34:$M34,MATCH($G34,'流量データ'!$C$2:$M$2,1)+1)}
A35: K1.8BRQ8 | B35: NQ408 | C35: -0.732 | D35: =SIGN(C35)*((L35-K35)/(N35-M35)*(ABS(C35)*1000/2-M35)+K35) -> -120.40803 | E35: ='電圧データ'!$D35/'電圧データ'!$C35*$D35 -> -1.7037736 | F35: =D35*E35/1000 -> 0.20514803 | G35: 10 | H35: =(R35-Q35)/(P35-O35)*(G35-O35)+Q35 -> 81 | I35: =F35/(H35/60)/4.1855 -> 0.036306654 | J35: 0.5 | K35: {=INDEX('磁場データ'!$C$2:$AB$2,MATCH(ABS($C35)*1000/2,'磁場データ'!$C35:$AB35,1))} -> 100 | L35: {=INDEX('磁場データ'!$C$2:$AB$2,MATCH(ABS($C35)*1000/2,'磁場データ'!$C35:$AB35,1)+1)} -> 200 | M35: {=INDEX('磁場データ'!$C35:$AB35,MATCH(ABS($C35)*1000/2,'磁場データ'!$C35:$AB35,1))} -> 306.671 | N35: {=INDEX('磁場データ'!$C35:$AB35,MATCH(ABS($C35)*1000/2,'磁場データ'!$C35:$AB35,1)+1)} -> 597.385 | O35: {=INDEX('流量データ'!$C$2:$M$2,MATCH($G35,'流量データ'!$C$2:$M$2,1))} -> 10 | P35: {=INDEX('流量データ'!$C$2:$M$2,MATCH($G35,'流量データ'!$C$2:$M$2,1)+1)} -> 11 | Q35: {=INDEX('流量データ'!$C35:$M35,MATCH($G35,'流量データ'!$C$2:$M$2,1))} -> 81 | R35: {=INDEX('流量データ'!$C35:$M35,MATCH($G35,'流量データ'!$C$2:$M$2,1)+1)}
A36: K1.8BRD5 | B36: 8D240S | C36: 17.98134 | D36: =SIGN(C36)*((L36-K36)/(N36-M36)*(ABS(C36)*1000-M36)+K36) -> 1848.9175 | E36: ='電圧データ'!$D36/'電圧データ'!$C36*$D36 -> 92.533919 | F36: =D36*E36/1000 -> 171.08758 | G36: 10 | H36: =(R36-Q36)/(P36-O36)*(G36-O36)+Q36 -> 118 | I36: =F36/(H36/60)/4.1855 -> 20.784538 | J36: 1 | K36: {=INDEX('磁場データ'!$C$2:$AB$2,MATCH(ABS($C36)*1000,'磁場データ'!$C36:$AB36,1))} -> 1800 | L36: {=INDEX('磁場データ'!$C$2:$AB$2,MATCH(ABS($C36)*1000,'磁場データ'!$C36:$AB36,1)+1)} -> 1900 | M36: {=INDEX('磁場データ'!$C36:$AB36,MATCH(ABS($C36)*1000,'磁場データ'!$C36:$AB36,1))} -> 17590 | N36: {=INDEX('磁場データ'!$C36:$AB36,MATCH(ABS($C36)*1000,'磁場データ'!$C36:$AB36,1)+1)} -> 18390 | O36: {=INDEX('流量データ'!$C$2:$M$2,MATCH($G36,'流量データ'!$C$2:$M$2,1))} -> 10 | P36: {=INDEX('流量データ'!$C$2:$M$2,MATCH($G36,'流量データ'!$C$2:$M$2,1)+1)} -> 11 | Q36: {=INDEX('流量データ'!$C36:$M36,MATCH($G36,'流量データ'!$C$2:$M$2,1))} -> 118 | R36: {=INDEX('流量データ'!$C36:$M36,MATCH($G36,'流量データ'!$C$2:$M$2,1)+1)}
A37: KLD1 | B37: 6D230 | C37: 20.7 | D37: =SIGN(C37)*((L37-K37)/(N37-M37)*(ABS(C37)*1000-M37)+K37) -> 2293.8031 | E37: ='電圧データ'!$D37/'電圧データ'!$C37*$D37 -> 117.48261 | F37: =D37*E37/1000 -> 269.48197 | G37: 10 | H37: =(R37-Q37)/(P37-O37)*(G37-O37)+Q37 -> 173 | I37: =F37/(H37/60)/4.1855 -> 22.329938 | J37: 1 | K37: {=INDEX('磁場データ'!$C$2:$AB$2,MATCH(ABS($C37)*1000,'磁場データ'!$C37:$AB37,1))} -> 2200 | L37: {=INDEX('磁場データ'!$C$2:$AB$2,MATCH(ABS($C37)*1000,'磁場データ'!$C37:$AB37,1)+1)} -> 2300 | M37: {=INDEX('磁場データ'!$C37:$AB37,MATCH(ABS($C37)*1000,'磁場データ'!$C37:$AB37,1))} -> 20258 | N37: {=INDEX('磁場データ'!$C37:$AB37,MATCH(ABS($C37)*1000,'磁場データ'!$C37:$AB37,1)+1)} -> 20729.2 | O37: {=INDEX('流量データ'!$C$2:$M$2,MATCH($G37,'流量データ'!$C$2:$M$2,1))} -> 10 | P37: {=INDEX('流量データ'!$C$2:$M$2,MATCH($G37,'流量データ'!$C$2:$M$2,1)+1)} -> 11 | Q37: {=INDEX('流量データ'!$C37:$M37,MATCH($G37,'流量データ'!$C$2:$M$2,1))} -> 173 | R37: {=INDEX('流量データ'!$C37:$M37,MATCH($G37,'流量データ'!$C$2:$M$2,1)+1)}
A38: KURAMA | B38: 20D1616 | C38: 10.56 | D38: =SIGN(C38)*((L38-K38)/(N38-M38)*(ABS(C38)*1000-M38)+K38) -> 2299.6815 | E38: ='電圧データ'!$D38/'電圧データ'!$C38*$D38 -> 159.78822 | F38: =D38*E38/1000 -> 367.46201 | G38: 10 | H38: =(R38-Q38)/(P38-O38)*(G38-O38)+Q38 -> 240 | I38: =F38/(H38/60)/4.1855 -> 21.948513 | J38: 1 | K38: {=INDEX('磁場データ'!$C$2:$AB$2,MATCH(ABS($C38)*1000,'磁場データ'!$C38:$AB38,1))} -> 2200 | L38: {=INDEX('磁場データ'!$C$2:$AB$2,MATCH(ABS($C38)*1000,'磁場データ'!$C38:$AB38,1)+1)} -> 2300 | M38: {=INDEX('磁場データ'!$C38:$AB38,MATCH(ABS($C38)*1000,'磁場データ'!$C38:$AB38,1))} -> 10247 | N38: {=INDEX('磁場データ'!$C38:$AB38,MATCH(ABS($C38)*1000,'磁場データ'!$C38:$AB38,1)+1)} -> 10561 | O38: {=INDEX('流量データ'!$C$2:$M$2,MATCH($G38,'流量データ'!$C$2:$M$2,1))} -> 10 | P38: {=INDEX('流量データ'!$C$2:$M$2,MATCH($G38,'流量データ'!$C$2:$M$2,1)+1)} -> 11 | Q38: {=INDEX('流量データ'!$C38:$M38,MATCH($G38,'流量データ'!$C$2:$M$2,1))} -> 240 | R38: {=INDEX('流量データ'!$C38:$M38,MATCH($G38,'流量データ'!$C$2:$M$2,1)+1)}

Sheet 電流→磁場
A1: 要素名 | B1: 型式 | C1: 電流 | D1: 磁場強度 | E1: 電圧 | F1: 電力 | G1: 差圧 | H1: 流量 | I1: 温度上昇 | J1: at-poleからのファクター | K1: 参照電流[A] | M1: 参照磁場強度[G] | O1: 参照差圧[kg/cm2] | Q1: 参照流量[l/min]
C2: [A] | D2: [kG] | E2: [V] | F2: [kW] | G2: [kg/cm2] | H2: [l/min] | I2: [K] | K2: #1 | L2: #2 | M2: #1 | N2: #2 | O2: #1 | P2: #2 | Q2: #1 | R2: #2
A3: K1.8D1 | B3: 5C216SMIC | C3: 562 | D3: =SIGN(C3)*((N3-M3)/(L3-K3)*(ABS(C3)-K3)+M3)/J3*0.001 -> 9.8720839 | E3: ='電圧データ'!$D3/'電圧データ'!$C3*$C3 -> 44.163833 | F3: =C3*E3/1000 -> 24.820074 | G3: 9 | H3: =(R3-Q3)/(P3-O3)*(G3-O3)+Q3 -> 114.63946 | I3: =F3/(H3/60)/4.1855 -> 3.1036507 | J3: 1 | K3: {=INDEX('磁場データ'!$C$2:$AB$2,MATCH(ABS($C3),'磁場データ'!$C$2:$AB$2,1))} -> 500 | L3: {=INDEX('磁場データ'!$C$2:$AB$2,MATCH(ABS($C3),'磁場データ'!$C$2:$AB$2,1)+1)} -> 600 | M3: {=INDEX('磁場データ'!$C3:$AB3,MATCH(ABS($C3),'磁場データ'!$C$2:$AB$2,1))} -> 8949.2009 | N3: {=INDEX('磁場データ'!$C3:$AB3,MATCH(ABS($C3),'磁場データ'!$C$2:$AB$2,1)+1)} -> 10437.722 | O3: {=INDEX('流量データ'!$C$2:$M$2,MATCH($G3,'流量データ'!$C$2:$M$2,1))} -> 9 | P3: {=INDEX('流量データ'!$C$2:$M$2,MATCH($G3,'流量データ'!$C$2:$M$2,1)+1)} -> 10 | Q3: {=INDEX('流量データ'!$C3:$M3,MATCH($G3,'流量データ'!$C$2:$M$2,1))} -> 114.63946 | R3: {=INDEX('流量データ'!$C3:$M3,MATCH($G3,'流量データ'!$C$2:$M$2,1)+1)} -> 121.75345
A4: K1.8Q1 | B4: NQ312MIC | C4: 534 | D4: =SIGN(C4)*((N4-M4)/(L4-K4)*(ABS(C4)-K4)+M4)/J4*0.001 -> 4.5839823 | E4: ='電圧データ'!$D4/'電圧データ'!$C4*$C4 -> 31.05655 | F4: =C4*E4/1000 -> 16.584198 | G4: 9 | H4: =(R4-Q4)/(P4-O4)*(G4-O4)+Q4 -> 121 | I4: =F4/(H4/60)/4.1855 -> 1.9647758 | J4: 0.5 | K4: {=INDEX('磁場データ'!$C$2:$AB$2,MATCH(ABS($C4),'磁場データ'!$C$2:$AB$2,1))} -> 500 | L4: {=INDEX('磁場データ'!$C$2:$AB$2,MATCH(ABS($C4),'磁場データ'!$C$2:$AB$2,1)+1)} -> 600 | M4: {=INDEX('磁場データ'!$C4:$AB4,MATCH(ABS($C4),'磁場データ'!$C$2:$AB$2,1))} -> 2148.4075 | N4: {=INDEX('磁場データ'!$C4:$AB4,MATCH(ABS($C4),'磁場データ'!$C$2:$AB$2,1)+1)} -> 2570.7123 | O4: {=INDEX('流量データ'!$C$2:$M$2,MATCH($G4,'流量データ'!$C$2:$M$2,1))} -> 9 | P4: {=INDEX('流量データ'!$C$2:$M$2,MATCH($G4,'流量データ'!$C$2:$M$2,1)+1)} -> 10 | Q4: {=INDEX('流量データ'!$C4:$M4,MATCH($G4,'流量データ'!$C$2:$M$2,1))} -> 121 | R4: {=INDEX('流量データ'!$C4:$M4,MATCH($G4,'流量データ'!$C$2:$M$2,1)+1)} -> 128
A5: K1.8Q2 | B5: Q416MIC | C5: 996 | D5: =SIGN(C5)*((N5-M5)/(L5-K5)*(ABS(C5)-K5)+M5)/J5*0.001 -> 5.7763589 | E5: ='電圧データ'!$D5/'電圧データ'!$C5*$C5 -> 26.502261 | F5: =C5*E5/1000 -> 26.396252 | G5: 10 | H5: =(R5-Q5)/(P5-O5)*(G5-O5)+Q5 -> 41 | I5: =F5/(H5/60)/4.1855 -> 9.2291629 | J5: 0.5 | K5: {=INDEX('磁場データ'!$C$2:$AB$2,MATCH(ABS($C5),'磁場データ'!$C$2:$AB$2,1))} -> 900 | L5: {=INDEX('磁場データ'!$C$2:$AB$2,MATCH(ABS($C5),'磁場データ'!$C$2:$AB$2,1)+1)} -> 1000 | M5: {=INDEX('磁場データ'!$C5:$AB5,MATCH(ABS($C5),'磁場データ'!$C$2:$AB$2,1))} -> 2611.0532 | N5: {=INDEX('磁場データ'!$C5:$AB5,MATCH(ABS($C5),'磁場データ'!$C$2:$AB$2,1)+1)} -> 2899.7264 | O5: {=INDEX('流量データ'!$C$2:$M$2,MATCH($G5,'流量データ'!$C$2:$M$2,1))} -> 10 | P5: {=INDEX('流量データ'!$C$2:$M$2,MATCH($G5,'流量データ'!$C$2:$M$2,1)+1)} -> 11 | Q5: {=INDEX('流量データ'!$C5:$M5,MATCH($G5,'流量データ'!$C$2:$M$2,1))} -> 41 | R5: {=INDEX('流量データ'!$C5:$M5,MATCH($G5,'流量データ'!$C$2:$M$2,1)+1)} -> 43
A6: K1.8D2 | B6: 8D218SMIC | C6: 1309 | D6: =SIGN(C6)*((N6-M6)/(L6-K6)*(ABS(C6)-K6)+M6)/J6*0.001 -> 15.774546 | E6: ='電圧データ'!$D6/'電圧データ'!$C6*$C6 -> 86.223261 | F6: =C6*E6/1000 -> 112.86625 | G6: 10 | H6: =(R6-Q6)/(P6-O6)*(G6-O6)+Q6 -> 125 | I6: =F6/(H6/60)/4.1855 -> 12.943686 | J6: 1 | K6: {=INDEX('磁場データ'!$C$2:$AB$2,MATCH(ABS($C6),'磁場データ'!$C$2:$AB$2,1))} -> 1300 | L6: {=INDEX('磁場データ'!$C$2:$AB$2,MATCH(ABS($C6),'磁場データ'!$C$2:$AB$2,1)+1)} -> 1400 | M6: {=INDEX('磁場データ'!$C6:$AB6,MATCH(ABS($C6),'磁場データ'!$C$2:$AB$2,1))} -> 15692.49 | N6: {=INDEX('磁場データ'!$C6:$AB6,MATCH(ABS($C6),'磁場データ'!$C$2:$AB$2,1)+1)} -> 16604.222 | O6: {=INDEX('流量データ'!$C$2:$M$2,MATCH($G6,'流量データ'!$C$2:$M$2,1))} -> 10 | P6: {=INDEX('流量データ'!$C$2:$M$2,MATCH($G6,'流量データ'!$C$2:$M$2,1)+1)} -> 11 | Q6: {=INDEX('流量データ'!$C6:$M6,MATCH($G6,'流量データ'!$C$2:$M$2,1))} -> 125 | R6: {=INDEX('流量データ'!$C6:$M6,MATCH($G6,'流量データ'!$C$2:$M$2,1)+1)} -> 132
A7: K1.8Q3 | B7: Q410 | C7: 1018 | D7: =SIGN(C7)*((N7-M7)/(L7-K7)*(ABS(C7)-K7)+M7)/J7*0.001 -> 6.1650789 | E7: ='電圧データ'!$D7/'電圧データ'!$C7*$C7 -> 48.308727 | F7: =C7*E7/1000 -> 49.178284 | G7: 5.5 | H7: =(R7-Q7)/(P7-O7)*(G7-O7)+Q7 -> 69 | I7: =F7/(H7/60)/4.1855 -> 10.217113 | J7: 0.5 | K7: {=INDEX('磁場データ'!$C$2:$AB$2,MATCH(ABS($C7),'磁場データ'!$C$2:$AB$2,1))} -> 1000 | L7: {=INDEX('磁場データ'!$C$2:$AB$2,MATCH(ABS($C7),'磁場データ'!$C$2:$AB$2,1)+1)} -> 1100 | M7: {=INDEX('磁場データ'!$C7:$AB7,MATCH(ABS($C7),'磁場データ'!$C$2:$AB$2,1))} -> 3028.0094 | N7: {=INDEX('磁場データ'!$C7:$AB7,MATCH(ABS($C7),'磁場データ'!$C$2:$AB$2,1)+1)} -> 3330.9542 | O7: {=INDEX('流量データ'!$C$2:$M$2,MATCH($G7,'流量データ'!$C$2:$M$2,1))} -> 5 | P7: {=INDEX('流量データ'!$C$2:$M$2,MATCH($G7,'流量データ'!$C$2:$M$2,1)+1)} -> 6 | Q7: {=INDEX('流量データ'!$C7:$M7,MATCH($G7,'流量データ'!$C$2:$M$2,1))} -> 65 | R7: {=INDEX('流量データ'!$C7:$M7,MATCH($G7,'流量データ'!$C$2:$M$2,1)+1)} -> 73
A8: K1.8O1 | B8: O503 | C8: 43 | D8: =SIGN(C8)*((N8-M8)/(L8-K8)*(ABS(C8)-K8)+M8)/J8*0.001 -> 0.8276 | E8: ='電圧データ'!$D8/'電圧データ'!$C8*$C8 -> 7.7744 | F8: =C8*E8/1000 -> 0.3342992 | G8: 5.5 | H8: =(R8-Q8)/(P8-O8)*(G8-O8)+Q8 -> 1.925 | I8: =F8/(H8/60)/4.1855 -> 2.4894792 | J8: 0.125 | K8: {=INDEX('磁場データ'!$C$2:$AB$2,MATCH(ABS($C8),'磁場データ'!$C$2:$AB$2,1))} -> 0 | L8: {=INDEX('磁場データ'!$C$2:$AB$2,MATCH(ABS($C8),'磁場データ'!$C$2:$AB$2,1)+1)} -> 100 | M8: {=INDEX('磁場データ'!$C8:$AB8,MATCH(ABS($C8),'磁場データ'!$C$2:$AB$2,1))} -> 0.25 | N8: {=INDEX('磁場データ'!$C8:$AB8,MATCH(ABS($C8),'磁場データ'!$C$2:$AB$2,1)+1)} -> 240.25 | O8: {=INDEX('流量データ'!$C$2:$M$2,MATCH($G8,'流量データ'!$C$2:$M$2,1))} -> 5 | P8: {=INDEX('流量データ'!$C$2:$M$2,MATCH($G8,'流量データ'!$C$2:$M$2,1)+1)} -> 6 | Q8: {=INDEX('流量データ'!$C8:$M8,MATCH($G8,'流量データ'!$C$2:$M$2,1))} -> 3.85 | R8: {=INDEX('流量データ'!$C8:$M8,MATCH($G8,'流量データ'!$C$2:$M$2,1)+1)}
A9: K1.8Q4 | B9: Q410 | C9: 1129 | D9: =SIGN(C9)*((N9-M9)/(L9-K9)*(ABS(C9)-K9)+M9)/J9*0.001 -> 6.8333988 | E9: ='電圧データ'!$D9/'電圧データ'!$C9*$C9 -> 53.473545 | F9: =C9*E9/1000 -> 60.371633 | G9: 5.5 | H9: =(R9-Q9)/(P9-O9)*(G9-O9)+Q9 -> 69 | I9: =F9/(H9/60)/4.1855 -> 12.542605 | J9: 0.5 | K9: {=INDEX('磁場データ'!$C$2:$AB$2,MATCH(ABS($C9),'磁場データ'!$C$2:$AB$2,1))} -> 1100 | L9: {=INDEX('磁場データ'!$C$2:$AB$2,MATCH(ABS($C9),'磁場データ'!$C$2:$AB$2,1)+1)} -> 1200 | M9: {=INDEX('磁場データ'!$C9:$AB9,MATCH(ABS($C9),'磁場データ'!$C$2:$AB$2,1))} -> 3329.0465 | N9: {=INDEX('磁場データ'!$C9:$AB9,MATCH(ABS($C9),'磁場データ'!$C$2:$AB$2,1)+1)} -> 3631.2978 | O9: {=INDEX('流量データ'!$C$2:$M$2,MATCH($G9,'流量データ'!$C$2:$M$2,1))} -> 5 | P9: {=INDEX('流量データ'!$C$2:$M$2,MATCH($G9,'流量データ'!$C$2:$M$2,1)+1)} -> 6 | Q9: {=INDEX('流量データ'!$C9:$M9,MATCH($G9,'流量データ'!$C$2:$M$2,1))} -> 65 | R9: {=INDEX('流量データ'!$C9:$M9,MATCH($G9,'流量データ'!$C$2:$M$2,1)+1)} -> 73
A10: K1.8S1 | B10: SX504 | C10: 50 | D10: =SIGN(C10)*((N10-M10)/(L10-K10)*(ABS(C10)-K10)+M10)/J10*0.001 -> 0.34799464 | E10: ='電圧データ'!$D10/'電圧データ'!$C10*$C10 -> 1.51 | F10: =C10*E10/1000 -> 0.0755 | G10: 5.5 | H10: =(R10-Q10)/(P10-O10)*(G10-O10)+Q10 -> 6 | I10: =F10/(H10/60)/4.1855 -> 0.18038466 | J10: 0.25 | K10: {=INDEX('磁場データ'!$C$2:$AB$2,MATCH(ABS($C10),'磁場データ'!$C$2:$AB$2,1))} -> 0 | L10: {=INDEX('磁場データ'!$C$2:$AB$2,MATCH(ABS($C10),'磁場データ'!$C$2:$AB$2,1)+1)} -> 100 | M10: {=INDEX('磁場データ'!$C10:$AB10,MATCH(ABS($C10),'磁場データ'!$C$2:$AB$2,1))} -> -1.9435079 | N10: {=INDEX('磁場データ'!$C10:$AB10,MATCH(ABS($C10),'磁場データ'!$C$2:$AB$2,1)+1)} -> 175.94083 | O10: {=INDEX('流量データ'!$C$2:$M$2,MATCH($G10,'流量データ'!$C$2:$M$2,1))} -> 5 | P10: {=INDEX('流量データ'!$C$2:$M$2,MATCH($G10,'流量データ'!$C$2:$M$2,1)+1)} -> 6 | Q10: {=INDEX('流量データ'!$C10:$M10,MATCH($G10,'流量データ'!$C$2:$M$2,1))} -> 12 | R10: {=INDEX('流量データ'!$C10:$M10,MATCH($G10,'流量データ'!$C$2:$M$2,1)+1)}
A11: K1.8CM1 | B11: 4D604V | C11: 348 | D11: =SIGN(C11)*((N11-M11)/(L11-K11)*(ABS(C11)-K11)+M11)/J11*0.001 -> 1.63288 | E11: ='電圧データ'!$D11/'電圧データ'!$C11*$C11 -> 13.94876 | F11: =C11*E11/1000 -> 4.8541686 | G11: 5.5 | H11: =(R11-Q11)/(P11-O11)*(G11-O11)+Q11 -> 20.5 | I11: =F11/(H11/60)/4.1855 -> 3.3944147 | J11: 1 | K11: {=INDEX('磁場データ'!$C$2:$AB$2,MATCH(ABS($C11),'磁場データ'!$C$2:$AB$2,1))} -> 300 | L11: {=INDEX('磁場データ'!$C$2:$AB$2,MATCH(ABS($C11),'磁場データ'!$C$2:$AB$2,1)+1)} -> 400 | M11: {=INDEX('磁場データ'!$C11:$AB11,MATCH(ABS($C11),'磁場データ'!$C$2:$AB$2,1))} -> 1414 | N11: {=INDEX('磁場データ'!$C11:$AB11,MATCH(ABS($C11),'磁場データ'!$C$2:$AB$2,1)+1)} -> 1870 | O11: {=INDEX('流量データ'!$C$2:$M$2,MATCH($G11,'流量データ'!$C$2:$M$2,1))} -> 5 | P11: {=INDEX('流量データ'!$C$2:$M$2,MATCH($G11,'流量データ'!$C$2:$M$2,1)+1)} -> 6 | Q11: {=INDEX('流量データ'!$C11:$M11,MATCH($G11,'流量データ'!$C$2:$M$2,1))} -> 19 | R11: {=INDEX('流量データ'!$C11:$M11,MATCH($G11,'流量データ'!$C$2:$M$2,1)+1)} -> 22
A12: K1.8CM2 | B12: 4D604V | C12: 348 | D12: =SIGN(C12)*((N12-M12)/(L12-K12)*(ABS(C12)-K12)+M12)/J12*0.001 -> 1.6304 | E12: ='電圧データ'!$D12/'電圧データ'!$C12*$C12 -> 13.92 | F12: =C12*E12/1000 -> 4.84416 | G12: 10 | H12: =(R12-Q12)/(P12-O12)*(G12-O12)+Q12 -> 30 | I12: =F12/(H12/60)/4.1855 -> 2.3147342 | J12: 1 | K12: {=INDEX('磁場データ'!$C$2:$AB$2,MATCH(ABS($C12),'磁場データ'!$C$2:$AB$2,1))} -> 300 | L12: {=INDEX('磁場データ'!$C$2:$AB$2,MATCH(ABS($C12),'磁場データ'!$C$2:$AB$2,1)+1)} -> 400 | M12: {=INDEX('磁場データ'!$C12:$AB12,MATCH(ABS($C12),'磁場データ'!$C$2:$AB$2,1))} -> 1412 | N12: {=INDEX('磁場データ'!$C12:$AB12,MATCH(ABS($C12),'磁場データ'!$C$2:$AB$2,1)+1)} -> 1867 | O12: {=INDEX('流量データ'!$C$2:$M$2,MATCH($G12,'流量データ'!$C$2:$M$2,1))} -> 10 | P12: {=INDEX('流量データ'!$C$2:$M$2,MATCH($G12,'流量データ'!$C$2:$M$2,1)+1)} -> 11 | Q12: {=INDEX('流量データ'!$C12:$M12,MATCH($G12,'流量データ'!$C$2:$M$2,1))} -> 30 | R12: {=INDEX('流量データ'!$C12:$M12,MATCH($G12,'流量データ'!$C$2:$M$2,1)+1)} -> 32
A13: K1.8S2 | B13: SX504 | C13: 127 | D13: =SIGN(C13)*((N13-M13)/(L13-K13)*(ABS(C13)-K13)+M13)/J13*0.001 -> 0.95139848 | E13: ='電圧データ'!$D13/'電圧データ'!$C13*$C13 -> 4.064 | F13: =C13*E13/1000 -> 0.516128 | G13: 10 | H13: =(R13-Q13)/(P13-O13)*(G13-O13)+Q13 -> 15 | I13: =F13/(H13/60)/4.1855 -> 0.49325337 | J13: 0.25 | K13: {=INDEX('磁場データ'!$C$2:$AB$2,MATCH(ABS($C13),'磁場データ'!$C$2:$AB$2,1))} -> 100 | L13: {=INDEX('磁場データ'!$C$2:$AB$2,MATCH(ABS($C13),'磁場データ'!$C$2:$AB$2,1)+1)} -> 200 | M13: {=INDEX('磁場データ'!$C13:$AB13,MATCH(ABS($C13),'磁場データ'!$C$2:$AB$2,1))} -> 188.25488 | N13: {=INDEX('磁場データ'!$C13:$AB13,MATCH(ABS($C13),'磁場データ'!$C$2:$AB$2,1)+1)} -> 371.93911 | O13: {=INDEX('流量データ'!$C$2:$M$2,MATCH($G13,'流量データ'!$C$2:$M$2,1))} -> 10 | P13: {=INDEX('流量データ'!$C$2:$M$2,MATCH($G13,'流量データ'!$C$2:$M$2,1)+1)} -> 11 | Q13: {=INDEX('流量データ'!$C13:$M13,MATCH($G13,'流量データ'!$C$2:$M$2,1))} -> 15 | R13: {=INDEX('流量データ'!$C13:$M13,MATCH($G13,'流量データ'!$C$2:$M$2,1)+1)} -> 16
A14: K1.8Q5 | B14: NQ510 | C14: 710 | D14: =SIGN(C14)*((N14-M14)/(L14-K14)*(ABS(C14)-K14)+M14)/J14*0.001 -> 6.0048766 | E14: ='電圧データ'!$D14/'電圧データ'!$C14*$C14 -> 39.100714 | F14: =C14*E14/1000 -> 27.761507 | G14: 10 | H14: =(R14-Q14)/(P14-O14)*(G14-O14)+Q14 -> 92 | I14: =F14/(H14/60)/4.1855 -> 4.3257271 | J14: 0.5 | K14: {=INDEX('磁場データ'!$C$2:$AB$2,MATCH(ABS($C14),'磁場データ'!$C$2:$AB$2,1))} -> 700 | L14: {=INDEX('磁場データ'!$C$2:$AB$2,MATCH(ABS($C14),'磁場データ'!$C$2:$AB$2,1)+1)} -> 800 | M14: {=INDEX('磁場データ'!$C14:$AB14,MATCH(ABS($C14),'磁場データ'!$C$2:$AB$2,1))} -> 2960.5109 | N14: {=INDEX('磁場データ'!$C14:$AB14,MATCH(ABS($C14),'磁場データ'!$C$2:$AB$2,1)+1)} -> 3379.7853 | O14: {=INDEX('流量データ'!$C$2:$M$2,MATCH($G14,'流量データ'!$C$2:$M$2,1))} -> 10 | P14: {=INDEX('流量データ'!$C$2:$M$2,MATCH($G14,'流量データ'!$C$2:$M$2,1)+1)} -> 11 | Q14: {=INDEX('流量データ'!$C14:$M14,MATCH($G14,'流量データ'!$C$2:$M$2,1))} -> 92 | R14: {=INDEX('流量データ'!$C14:$M14,MATCH($G14,'流量データ'!$C$2:$M$2,1)+1)}
A15: K1.8Q6 | B15: NQ610 | C15: 840 | D15: =SIGN(C15)*((N15-M15)/(L15-K15)*(ABS(C15)-K15)+M15)/J15*0.001 -> 6.7508147 | E15: ='電圧データ'!$D15/'電圧データ'!$C15*$C15 -> 50.152941 | F15: =C15*E15/1000 -> 42.128471 | G15: 10 | H15: =(R15-Q15)/(P15-O15)*(G15-O15)+Q15 -> 103 | I15: =F15/(H15/60)/4.1855 -> 5.8633035 | J15: =80/150 -> 0.53333333 | K15: {=INDEX('磁場データ'!$C$2:$AB$2,MATCH(ABS($C15),'磁場データ'!$C$2:$AB$2,1))} -> 800 | L15: {=INDEX('磁場データ'!$C$2:$AB$2,MATCH(ABS($C15),'磁場データ'!$C$2:$AB$2,1)+1)} -> 900 | M15: {=INDEX('磁場データ'!$C15:$AB15,MATCH(ABS($C15),'磁場データ'!$C$2:$AB$2,1))} -> 3431.05 | N15: {=INDEX('磁場データ'!$C15:$AB15,MATCH(ABS($C15),'磁場データ'!$C$2:$AB$2,1)+1)} -> 3854.5113 | O15: {=INDEX('流量データ'!$C$2:$M$2,MATCH($G15,'流量データ'!$C$2:$M$2,1))} -> 10 | P15: {=INDEX('流量データ'!$C$2:$M$2,MATCH($G15,'流量データ'!$C$2:$M$2,1)+1)} -> 11 | Q15: {=INDEX('流量データ'!$C15:$M15,MATCH($G15,'流量データ'!$C$2:$M$2,1))} -> 103 | R15: {=INDEX('流量データ'!$C15:$M15,MATCH($G15,'流量データ'!$C$2:$M$2,1)+1)} -> 108
A16: K1.8D3 | B16: 6D330S | C16: 378 | D16: =SIGN(C16)*((N16-M16)/(L16-K16)*(ABS(C16)-K16)+M16)/J16*0.001 -> 12.530643 | E16: ='電圧データ'!$D16/'電圧データ'!$C16*$C16 -> 99.5652 | F16: =C16*E16/1000 -> 37.635646 | G16: 10 | H16: =(R16-Q16)/(P16-O16)*(G16-O16)+Q16 -> 103 | I16: =F16/(H16/60)/4.1855 -> 5.2380067 | J16: 1 | K16: {=INDEX('磁場データ'!$C$2:$AB$2,MATCH(ABS($C16),'磁場データ'!$C$2:$AB$2,1))} -> 300 | L16: {=INDEX('磁場データ'!$C$2:$AB$2,MATCH(ABS($C16),'磁場データ'!$C$2:$AB$2,1)+1)} -> 400 | M16: {=INDEX('磁場データ'!$C16:$AB16,MATCH(ABS($C16),'磁場データ'!$C$2:$AB$2,1))} -> 10063.051 | N16: {=INDEX('磁場データ'!$C16:$AB16,MATCH(ABS($C16),'磁場データ'!$C$2:$AB$2,1)+1)} -> 13226.63 | O16: {=INDEX('流量データ'!$C$2:$M$2,MATCH($G16,'流量データ'!$C$2:$M$2,1))} -> 10 | P16: {=INDEX('流量データ'!$C$2:$M$2,MATCH($G16,'流量データ'!$C$2:$M$2,1)+1)} -> 11 | Q16: {=INDEX('流量データ'!$C16:$M16,MATCH($G16,'流量データ'!$C$2:$M$2,1))} -> 103 | R16: {=INDEX('流量データ'!$C16:$M16,MATCH($G16,'流量データ'!$C$2:$M$2,1)+1)} -> 108
A17: K1.8Q7 | B17: NQ408 | C17: 643 | D17: =SIGN(C17)*((N17-M17)/(L17-K17)*(ABS(C17)-K17)+M17)/J17*0.001 -> 3.7603918 | E17: ='電圧データ'!$D17/'電圧データ'!$C17*$C17 -> 9.16275 | F17: =C17*E17/1000 -> 5.8916483 | G17: 10 | H17: =(R17-Q17)/(P17-O17)*(G17-O17)+Q17 -> 75 | I17: =F17/(H17/60)/4.1855 -> 1.1261065 | J17: 0.5 | K17: {=INDEX('磁場データ'!$C$2:$AB$2,MATCH(ABS($C17),'磁場データ'!$C$2:$AB$2,1))} -> 600 | L17: {=INDEX('磁場データ'!$C$2:$AB$2,MATCH(ABS($C17),'磁場データ'!$C$2:$AB$2,1)+1)} -> 700 | M17: {=INDEX('磁場データ'!$C17:$AB17,MATCH(ABS($C17),'磁場データ'!$C$2:$AB$2,1))} -> 1758.45 | N17: {=INDEX('磁場データ'!$C17:$AB17,MATCH(ABS($C17),'磁場データ'!$C$2:$AB$2,1)+1)} -> 2041.58 | O17: {=INDEX('流量データ'!$C$2:$M$2,MATCH($G17,'流量データ'!$C$2:$M$2,1))} -> 10 | P17: {=INDEX('流量データ'!$C$2:$M$2,MATCH($G17,'流量データ'!$C$2:$M$2,1)+1)} -> 11 | Q17: {=INDEX('流量データ'!$C17:$M17,MATCH($G17,'流量データ'!$C$2:$M$2,1))} -> 75 | R17: {=INDEX('流量データ'!$C17:$M17,MATCH($G17,'流量データ'!$C$2:$M$2,1)+1)} -> 83
A18: K1.8O2 | B18: O603 | C18: 33 | D18: =SIGN(C18)*((N18-M18)/(L18-K18)*(ABS(C18)-K18)+M18)/J18*0.001 -> 0.29438 | E18: ='電圧データ'!$D18/'電圧データ'!$C18*$C18 -> 1.7226 | F18: =C18*E18/1000 -> 0.0568458 | G18: 10 | H18: =(R18-Q18)/(P18-O18)*(G18-O18)+Q18 -> 10.5 | I18: =F18/(H18/60)/4.1855 -> 0.077609161 | J18: 0.125 | K18: {=INDEX('磁場データ'!$C$2:$AB$2,MATCH(ABS($C18),'磁場データ'!$C$2:$AB$2,1))} -> 0 | L18: {=INDEX('磁場データ'!$C$2:$AB$2,MATCH(ABS($C18),'磁場データ'!$C$2:$AB$2,1)+1)} -> 100 | M18: {=INDEX('磁場データ'!$C18:$AB18,MATCH(ABS($C18),'磁場データ'!$C$2:$AB$2,1))} -> 0.25 | N18: {=INDEX('磁場データ'!$C18:$AB18,MATCH(ABS($C18),'磁場データ'!$C$2:$AB$2,1)+1)} -> 111 | O18: {=INDEX('流量データ'!$C$2:$M$2,MATCH($G18,'流量データ'!$C$2:$M$2,1))} -> 10 | P18: {=INDEX('流量データ'!$C$2:$M$2,MATCH($G18,'流量データ'!$C$2:$M$2,1)+1)} -> 11 | Q18: {=INDEX('流量データ'!$C18:$M18,MATCH($G18,'流量データ'!$C$2:$M$2,1))} -> 10.5 | R18: {=INDEX('流量データ'!$C18:$M18,MATCH($G18,'流量データ'!$C$2:$M$2,1)+1)}
A19: K1.8S3 | B19: SX604 | C19: 129 | D19: =SIGN(C19)*((N19-M19)/(L19-K19)*(ABS(C19)-K19)+M19)/J19*0.001 -> 0.87836 | E19: ='電圧データ'!$D19/'電圧データ'!$C19*$C19 -> 4.4433333 | F19: =C19*E19/1000 -> 0.57319 | G19: 10 | H19: =(R19-Q19)/(P19-O19)*(G19-O19)+Q19 -> 19.6 | I19: =F19/(H19/60)/4.1855 -> 0.41922429 | J19: 0.25 | K19: {=INDEX('磁場データ'!$C$2:$AB$2,MATCH(ABS($C19),'磁場データ'!$C$2:$AB$2,1))} -> 100 | L19: {=INDEX('磁場データ'!$C$2:$AB$2,MATCH(ABS($C19),'磁場データ'!$C$2:$AB$2,1)+1)} -> 200 | M19: {=INDEX('磁場データ'!$C19:$AB19,MATCH(ABS($C19),'磁場データ'!$C$2:$AB$2,1))} -> 170 | N19: {=INDEX('磁場データ'!$C19:$AB19,MATCH(ABS($C19),'磁場データ'!$C$2:$AB$2,1)+1)} -> 341 | O19: {=INDEX('流量データ'!$C$2:$M$2,MATCH($G19,'流量データ'!$C$2:$M$2,1))} -> 10 | P19: {=INDEX('流量データ'!$C$2:$M$2,MATCH($G19,'流量データ'!$C$2:$M$2,1)+1)} -> 11 | Q19: {=INDEX('流量データ'!$C19:$M19,MATCH($G19,'流量データ'!$C$2:$M$2,1))} -> 19.6 | R19: {=INDEX('流量データ'!$C19:$M19,MATCH($G19,'流量データ'!$C$2:$M$2,1)+1)}
A20: K1.8CM3 | B20: 4D604V | C20: 306 | D20: =SIGN(C20)*((N20-M20)/(L20-K20)*(ABS(C20)-K20)+M20)/J20*0.001 -> 1.44136 | E20: ='電圧データ'!$D20/'電圧データ'!$C20*$C20 -> 11.835372 | F20: =C20*E20/1000 -> 3.6216238 | G20: 10 | H20: =(R20-Q20)/(P20-O20)*(G20-O20)+Q20 -> 32.8 | I20: =F20/(H20/60)/4.1855 -> 1.5828268 | J20: 1 | K20: {=INDEX('磁場データ'!$C$2:$AB$2,MATCH(ABS($C20),'磁場データ'!$C$2:$AB$2,1))} -> 300 | L20: {=INDEX('磁場データ'!$C$2:$AB$2,MATCH(ABS($C20),'磁場データ'!$C$2:$AB$2,1)+1)} -> 400 | M20: {=INDEX('磁場データ'!$C20:$AB20,MATCH(ABS($C20),'磁場データ'!$C$2:$AB$2,1))} -> 1414 | N20: {=INDEX('磁場データ'!$C20:$AB20,MATCH(ABS($C20),'磁場データ'!$C$2:$AB$2,1)+1)} -> 1870 | O20: {=INDEX('流量データ'!$C$2:$M$2,MATCH($G20,'流量データ'!$C$2:$M$2,1))} -> 10 | P20: {=INDEX('流量データ'!$C$2:$M$2,MATCH($G20,'流量データ'!$C$2:$M$2,1)+1)} -> 11 | Q20: {=INDEX('流量データ'!$C20:$M20,MATCH($G20,'流量データ'!$C$2:$M$2,1))} -> 32.8 | R20: {=INDEX('流量データ'!$C20:$M20,MATCH($G20,'流量データ'!$C$2:$M$2,1)+1)}
A21: K1.8CM4 | B21: 4D604V | C21: 306 | D21: =SIGN(C21)*((N21-M21)/(L21-K21)*(ABS(C21)-K21)+M21)/J21*0.001 -> 1.44136 | E21: ='電圧データ'!$D21/'電圧データ'!$C21*$C21 -> 11.91124 | F21: =C21*E21/1000 -> 3.6448393 | G21: 10 | H21: =(R21-Q21)/(P21-O21)*(G21-O21)+Q21 -> 33.6 | I21: =F21/(H21/60)/4.1855 -> 1.5550452 | J21: 1 | K21: {=INDEX('磁場データ'!$C$2:$AB$2,MATCH(ABS($C21),'磁場データ'!$C$2:$AB$2,1))} -> 300 | L21: {=INDEX('磁場データ'!$C$2:$AB$2,MATCH(ABS($C21),'磁場データ'!$C$2:$AB$2,1)+1)} -> 400 | M21: {=INDEX('磁場データ'!$C21:$AB21,MATCH(ABS($C21),'磁場データ'!$C$2:$AB$2,1))} -> 1414 | N21: {=INDEX('磁場データ'!$C21:$AB21,MATCH(ABS($C21),'磁場データ'!$C$2:$AB$2,1)+1)} -> 1870 | O21: {=INDEX('流量データ'!$C$2:$M$2,MATCH($G21,'流量データ'!$C$2:$M$2,1))} -> 10 | P21: {=INDEX('流量データ'!$C$2:$M$2,MATCH($G21,'流量データ'!$C$2:$M$2,1)+1)} -> 11 | Q21: {=INDEX('流量データ'!$C21:$M21,MATCH($G21,'流量データ'!$C$2:$M$2,1))} -> 33.6 | R21: {=INDEX('流量データ'!$C21:$M21,MATCH($G21,'流量データ'!$C$2:$M$2,1)+1)}
A22: K1.8S4 | B22: SX604 | C22: 29 | D22: =SIGN(C22)*((N22-M22)/(L22-K22)*(ABS(C22)-K22)+M22)/J22*0.001 -> 0.2012 | E22: ='電圧データ'!$D22/'電圧データ'!$C22*$C22 -> 0.99888889 | F22: =C22*E22/1000 -> 0.028967778 | G22: 10 | H22: =(R22-Q22)/(P22-O22)*(G22-O22)+Q22 -> 19.6 | I22: =F22/(H22/60)/4.1855 -> 0.021186685 | J22: 0.25 | K22: {=INDEX('磁場データ'!$C$2:$AB$2,MATCH(ABS($C22),'磁場データ'!$C$2:$AB$2,1))} -> 0 | L22: {=INDEX('磁場データ'!$C$2:$AB$2,MATCH(ABS($C22),'磁場データ'!$C$2:$AB$2,1)+1)} -> 100 | M22: {=INDEX('磁場データ'!$C22:$AB22,MATCH(ABS($C22),'磁場データ'!$C$2:$AB$2,1))} -> 1 | N22: {=INDEX('磁場データ'!$C22:$AB22,MATCH(ABS($C22),'磁場データ'!$C$2:$AB$2,1)+1)} -> 171 | O22: {=INDEX('流量データ'!$C$2:$M$2,MATCH($G22,'流量データ'!$C$2:$M$2,1))} -> 10 | P22: {=INDEX('流量データ'!$C$2:$M$2,MATCH($G22,'流量データ'!$C$2:$M$2,1)+1)} -> 11 | Q22: {=INDEX('流量データ'!$C22:$M22,MATCH($G22,'流量データ'!$C$2:$M$2,1))} -> 19.6 | R22: {=INDEX('流量データ'!$C22:$M22,MATCH($G22,'流量データ'!$C$2:$M$2,1)+1)}
