Workbook
Name tmp: expect_KOT!#REF!
Name tmp: expect_kW!#REF!

Sheet user time
B1: Run78 User Time
B3: date | C3: MR | D3: beam condition | E3: run | F3: start time | G3: end time | H3: duration | I3: down time | J3: up time | K3: up time ratio | M3: date | N3: beam stop | O3: beam start | P3: down | R3: date | S3: beam stop | T3: beam start | U3: down | W3: date | X3: beam stop | Y3: beam start | Z3: down
A4: Run#78 | B4: 43117 | C4: 10.5kW | D4: -1.0 GeV/c | E4: system launch | F4: 0.7653588 | G4: 0.87152778 | H4: =G4-F4 -> 0.10616898 | I4: =E46 -> 0.052488426 | J4: =H4-I4 -> 0.053680556 | K4: =J4/H4 -> 0.5056143 | M4: 43154 | N4: 0.008912037 | O4: 0.013009259 | P4: =O4-N4 -> 0.0040972222 | R4: 43155 | S4: 0.011736111 | T4: 0.012511574 | U4: =T4-S4 -> 0.00077546296 | V4: 782 | W4: 43156 | X4: 0.0084027778 | Y4: 0.008912037 | Z4: =Y4-X4 -> 0.00050925926 | AA4: 807
B5: 43118 | C5: 31.5kW | D5: -1.0 GeV/c | E5: system launch, emtpy run | F5: 0.45835648 | G5: 1 | H5: =G5-F5 -> 0.54164352 | I5: =E75 -> 0.14743056 | J5: =H5-I5 -> 0.39421296 | K5: =J5/H5 -> 0.72780888 | N5: 0.034375 | O5: 0.034814815 | P5: =O5-N5 -> 0.00043981481 | Q5: 756 | S5: 0.013194444 | T5: 0.013576389 | U5: =T5-S5 -> 0.00038194444 | V5: 782 | X5: 0.062673611 | Y5: 0.063078704 | Z5: =Y5-X5 -> 0.00040509259 | AA5: 808
B6: 43119 | C6: 31.5kW | D6: -1.0 GeV/c | E6: empty run | F6: 0 | G6: 0.039918981 | H6: =G6-F6 -> 0.039918981 | I6: =E81 -> 0.0083564815 | J6: =H6-I6 -> 0.0315625 | K6: =J6/H6 -> 0.79066396 | N6: 0.040185185 | O6: 0.040451389 | P6: =O6-N6 -> 0.0002662037 | Q6: 756 | S6: 0.06869213 | T6: 0.0690625 | U6: =T6-S6 -> 0.00037037037 | V6: 783 | X6: 0.15403935 | Y6: 0.15443287 | Z6: =Y6-X6 -> 0.00039351852 | AA6: 810
C7: 31.5kW | D7: -1.0 GeV/c | E7: test production run | F7: 0.83702546 | G7: 1 | H7: =G7-F7 -> 0.16297454 | I7: =E88 -> 0.022638889 | J7: =H7-I7 -> 0.14033565 | K7: =J7/H7 -> 0.86108941 | N7: 0.070451389 | O7: 0.070856481 | P7: =O7-N7 -> 0.00040509259 | Q7: 757 | S7: 0.086296296 | T7: 0.086539352 | U7: =T7-S7 -> 0.00024305556 | V7: 784 | X7: 0.19332176 | Y7: 0.19376157 | Z7: =Y7-X7 -> 0.00043981481 | AA7: 811
B8: 43120 | C8: 31.5kW | D8: -1.0 GeV/c | E8: test production run | F8: 0 | G8: 0.37498843 | H8: =G8-F8 -> 0.37498843 | I8: =E107 -> 0.020601852 | J8: =H8-I8 -> 0.35438657 | K8: =J8/H8 -> 0.94506003 | N8: 0.12690972 | O8: 0.12778935 | P8: =O8-N8 -> 0.00087962963 | Q8: 758 | S8: 0.093472222 | T8: 0.12857639 | U8: =T8-S8 -> 0.035104167 | V8: 784end/785start | X8: 0.20180556 | Y8: 0.20212963 | Z8: =Y8-X8 -> 0.00032407407 | AA8: 811
B9: 43125 | C9: 33.5kW | D9: -1.0 GeV/c | E9: production run | F9: 0.97462963 | G9: 1 | H9: =G9-F9 -> 0.02537037 | I9: =E112 -> 0 | J9: =H9-I9 -> 0.02537037 | K9: =J9/H9 -> 1 | L9: cycle was changed to 5.2s | N9: 0.16896991 | O9: 0.16940972 | P9: =O9-N9 -> 0.00043981481 | Q9: 762 | S9: 0.13872685 | T9: 0.13907407 | U9: =T9-S9 -> 0.00034722222 | V9: 785 | X9: 0.20748843 | Y9: 0.21621528 | Z9: =Y9-X9 -> 0.0087268519 | AA9: 811end/812start
B10: 43126 | C10: 33.5kW | D10: -1.0 GeV/c | E10: production run | F10: 0 | G10: 0.42759259 | H10: =G10-F10 -> 0.42759259 | I10: =E134 -> 0.051828704 | J10: =H10-I10 -> 0.37576389 | K10: =J10/H10 -> 0.87878952 | N10: 0.19398148 | O10: 0.19575231 | P10: =O10-N10 -> 0.0017708333 | Q10: 762end | S10: 0.14341435 | T10: 0.14385417 | U10: =T10-S10 -> 0.00043981481 | V10: 785 | Y10: total | Z10: =SUM(Z4:Z9) -> 0.010798611
C11: 44.5kW | D11: -1.0 GeV/c | E11: production run | F11: 0.97362269 | G11: 1 | H11: =G11-F11 -> 0.026377315 | I11: =E137 -> 0.014537037 | J11: =H11-I11 -> 0.011840278 | K11: =J11/H11 -> 0.44888109 | N11: 0.23982639 | O11: 0.2402662 | P11: =O11-N11 -> 0.00043981481 | Q11: 764 | S11: 0.15596065 | T11: 0.15635417 | U11: =T11-S11 -> 0.00039351852 | V11: 785
B12: 43127 | C12: 44.5kW | D12: -1.0 GeV/c | E12: production run | F12: 0 | G12: 0.44570602 | H12: =G12-F12 -> 0.44570602 | I12: =E159 -> 0.083530093 | J12: =H12-I12 -> 0.36217593 | K12: =J12/H12 -> 0.81258926 | N12: 0.25922454 | O12: 0.25950231 | P12: =O12-N12 -> 0.00027777778 | Q12: 764 | S12: 0.16899306 | T12: 0.17487269 | U12: =T12-S12 -> 0.0058796296 | V12: 786
B13: 43128 | C13: 44.5kW | D13: -1.0 GeV/c | E13: production run | F13: 0.0015972222 | G13: 1 | H13: =G13-F13 -> 0.99840278 | I13: =E191 -> 0.14377315 | J13: =H13-I13 -> 0.85462963 | K13: =J13/H13 -> 0.85599685 | N13: 0.27043981 | O13: 0.27078704 | P13: =O13-N13 -> 0.00034722222 | Q13: 764 | S13: 0.18502315 | T13: 0.18534722 | U13: =T13-S13 -> 0.00032407407 | V13: 786
B14: 43129 | C14: 44.5kW | D14: -1.0 GeV/c | E14: production run | F14: 0 | G14: 1 | H14: =G14-F14 -> 1 | I14: =J80 -> 0.10299769 | J14: =H14-I14 -> 0.89700231 | K14: =J14/H14 -> 0.89700231 | N14: 0.27805556 | O14: 0.27855324 | P14: =O14-N14 -> 0.00049768519 | Q14: 764 | S14: 0.2072338 | T14: 0.2075463 | U14: =T14-S14 -> 0.0003125 | V14: 786
B15: 43130 | C15: 44.5kW | D15: -1.0 GeV/c | E15: production run | F15: 0 | G15: 0.42703704 | H15: =G15-F15 -> 0.42703704 | I15: =J99 -> 0.060821759 | J15: =H15-I15 -> 0.36621528 | K15: =J15/H15 -> 0.85757264 | N15: 0.30122685 | O15: 0.30173611 | P15: =O15-N15 -> 0.00050925926 | Q15: 765 | S15: 0.25247685 | T15: 0.25284722 | U15: =T15-S15 -> 0.00037037037 | V15: 787
C16: 49.8kW | D16: -1.0 GeV/c | E16: production run | F16: 0.76025463 | G16: 1 | H16: =G16-F16 -> 0.23974537 | I16: =J106 -> 0.070833333 | J16: =H16-I16 -> 0.16891204 | K16: =J16/H16 -> 0.70454765 | N16: 0.30185185 | O16: 0.30322917 | P16: =O16-N16 -> 0.0013773148 | Q16: 765 | S16: 0.25872685 | T16: 0.25916667 | U16: =T16-S16 -> 0.00043981481 | V16: 788
B17: 43131 | C17: 49.8kW | D17: -1.0 GeV/c | E17: production run | F17: 0 | G17: 0.37502315 | H17: =G17-F17 -> 0.37502315 | I17: =J125 -> 0.0403125 | J17: =H17-I17 -> 0.33471065 | K17: =J17/H17 -> 0.89250664 | N17: 0.30709491 | O17: 0.30756944 | P17: =O17-N17 -> 0.00047453704 | Q17: 765 | S17: 0.26913194 | T17: 0.2696875 | U17: =T17-S17 -> 0.00055555556 | V17: 788
B18: 43132 | C18: 50.7kW | D18: -1.0 GeV/c | E18: production run | F18: 0.66680556 | G18: 1 | H18: =G18-F18 -> 0.33319444 | I18: =J143 -> 0.068831019 | J18: =H18-I18 -> 0.26436343 | K18: =J18/H18 -> 0.79342087 | L18: beam-power calibration was changed | N18: 0.34113426 | O18: 0.34163194 | P18: =O18-N18 -> 0.00049768519 | Q18: 766 | S18: 0.29700231 | T18: 0.29748843 | U18: =T18-S18 -> 0.00048611111 | V18: 788
B19: 43133 | C19: 50.7kW | D19: -1.0 GeV/c | E19: production run | F19: 0 | G19: 1 | H19: =G19-F19 -> 1 | I19: =J188 -> 0.086724537 | J19: =H19-I19 -> 0.91327546 | K19: =J19/H19 -> 0.91327546 | N19: 0.35239583 | O19: 0.35267361 | P19: =O19-N19 -> 0.00027777778 | Q19: 766 | S19: 0.31939815 | T19: 0.32385417 | U19: =T19-S19 -> 0.0044560185 | V19: 789
B20: 43134 | C20: 50.7kW | D20: -1.0 GeV/c | E20: production run | F20: 0 | G20: 1 | H20: =G20-F20 -> 1 | I20: =P107 -> 0.044606481 | J20: =H20-I20 -> 0.95539352 | K20: =J20/H20 -> 0.95539352 | N20: 0.39662037 | O20: 0.39905093 | P20: =O20-N20 -> 0.0024305556 | Q20: 767 | S20: 0.33571759 | T20: 0.33619213 | U20: =T20-S20 -> 0.00047453704 | V20: 789
B21: 43135 | C21: 50.8kW | D21: -1.0 GeV/c | E21: production run | F21: 0 | G21: 1 | H21: =G21-F21 -> 1 | I21: =P149 -> 0.067083333 | J21: =H21-I21 -> 0.93291667 | K21: =J21/H21 -> 0.93291667 | N21: 0.42099537 | O21: 0.42143519 | P21: =O21-N21 -> 0.00043981481 | Q21: 768 | S21: 0.34314815 | T21: 0.34342593 | U21: =T21-S21 -> 0.00027777778 | V21: 789
B22: 43136 | C22: 50.8kW | D22: -1.0 GeV/c | E22: production run | F22: 0 | G22: 1 | H22: =G22-F22 -> 1 | I22: =P188 -> 0.059456019 | J22: =H22-I22 -> 0.94054398 | K22: =J22/H22 -> 0.94054398 | N22: 0.44217593 | O22: 0.44420139 | P22: =O22-N22 -> 0.002025463 | Q22: 768 | S22: 0.39471065 | T22: 0.39512731 | U22: =T22-S22 -> 0.00041666667 | V22: 791
B23: 43137 | C23: 50.8kW | D23: -1.0 GeV/c | E23: production run | F23: 0 | G23: 1 | H23: =G23-F23 -> 1 | I23: =U106 -> 0.19655093 | J23: =H23-I23 -> 0.80344907 | K23: =J23/H23 -> 0.80344907 | N23: 0.44447917 | O23: 0.44479167 | P23: =O23-N23 -> 0.0003125 | Q23: 768 | S23: 0.3991088 | T23: 0.39950231 | U23: =T23-S23 -> 0.00039351852 | V23: 791
B24: 43138 | C24: 50.8kW | D24: -1.0 GeV/c | E24: production run | F24: 0 | G24: 0.37502315 | H24: =G24-F24 -> 0.37502315 | I24: =U122 -> 0.050150463 | J24: =H24-I24 -> 0.32487269 | K24: =J24/H24 -> 0.86627369 | N24: 0.46204861 | O24: 0.47630787 | P24: =O24-N24 -> 0.014259259 | Q24: 769 | S24: 0.41739583 | T24: 0.41784722 | U24: =T24-S24 -> 0.00045138889 | V24: 791
B25: 43139 | C25: 50.3kW | D25: -1.0 GeV/c | E25: production run | F25: 0.40747685 | G25: 1 | H25: =G25-F25 -> 0.59252315 | I25: =U145 -> 0.029814815 | J25: =H25-I25 -> 0.56270833 | K25: =J25/H25 -> 0.9496816 | N25: 0.47811343 | O25: 0.48765046 | P25: =O25-N25 -> 0.009537037 | Q25: 769 | S25: 0.53172454 | T25: 0.53216435 | U25: =T25-S25 -> 0.00043981481 | V25: 794
B26: 43140 | C26: 50.3kW | D26: -1.0 GeV/c | E26: production run | F26: 0 | G26: 1 | H26: =G26-F26 -> 1 | I26: =U190 -> 0.10009259 | J26: =H26-I26 -> 0.89990741 | K26: =J26/H26 -> 0.89990741 | N26: 0.4962963 | O26: 0.49658565 | P26: =O26-N26 -> 0.00028935185 | Q26: 770 | S26: 0.58135417 | T26: 0.60840278 | U26: =T26-S26 -> 0.027048611 | V26: 795end/796start
B27: 43141 | C27: 50.3kW | D27: -1.0 GeV/c | E27: production run | F27: 0 | G27: 0.37501157 | H27: =G27-F27 -> 0.37501157 | I27: =U208 -> 0.032777778 | J27: =H27-I27 -> 0.3422338 | K27: =J27/H27 -> 0.91259529 | N27: 0.53483796 | O27: 0.53523148 | P27: =O27-N27 -> 0.00039351852 | Q27: 770 | S27: 0.60878472 | T27: 0.60931713 | U27: =T27-S27 -> 0.00053240741 | V27: 796
B28: 43146 | C28: 49.6kW | D28: -1.0 GeV/c | E28: production run | F28: 0.017719907 | G28: 1 | H28: =G28-F28 -> 0.98228009 | I28: =Z110 -> 0.069421296 | J28: =H28-I28 -> 0.9128588 | K28: =J28/H28 -> 0.92932637 | N28: 0.60210648 | O28: 0.60667824 | P28: =O28-N28 -> 0.0045717593 | Q28: 772 | S28: 0.71034722 | T28: 0.71070602 | U28: =T28-S28 -> 0.0003587963 | V28: 798
B29: 43147 | C29: 49.8kW | D29: -1.0 GeV/c | E29: production run | F29: 0 | G29: 1 | H29: =G29-F29 -> 1 | I29: =Z152 -> 0.30855324 | J29: =H29-I29 -> 0.69144676 | K29: =J29/H29 -> 0.69144676 | N29: 0.62332176 | O29: 0.62383102 | P29: =O29-N29 -> 0.00050925926 | Q29: 772end/773start | S29: 0.77229167 | T29: 0.77309028 | U29: =T29-S29 -> 0.00079861111 | V29: 801
B30: 43148 | C30: 50.4kW | D30: -1.0 GeV/c | E30: production run | F30: 0 | G30: 1 | H30: =G30-F30 -> 1 | I30: =Z184 -> 0.71131944 | J30: =H30-I30 -> 0.28868056 | K30: =J30/H30 -> 0.28868056 | N30: 0.67320602 | O30: 0.67642361 | P30: =O30-N30 -> 0.0032175926 | Q30: 774 | S30: 0.78998843 | T30: 0.79019676 | U30: =T30-S30 -> 0.00020833333 | V30: 802
B31: 43149 | C31: 50.4kW | D31: -1.0 GeV/c | E31: production run | F31: 0 | G31: 1 | H31: =G31-F31 -> 1 | I31: =AE131 -> 0.050243056 | J31: =H31-I31 -> 0.94975694 | K31: =J31/H31 -> 0.94975694 | N31: 0.71125 | O31: 0.71168981 | P31: =O31-N31 -> 0.00043981481 | Q31: 775 | S31: 0.82394676 | T31: 0.8243287 | U31: =T31-S31 -> 0.00038194444 | V31: 802
B32: 43150 | C32: 50.4kW | D32: -1.0 GeV/c | E32: production run | F32: 0 | G32: 1 | H32: =G32-F32 -> 1 | I32: =AE170 -> 0.029861111 | J32: =H32-I32 -> 0.97013889 | K32: =J32/H32 -> 0.97013889 | N32: 0.73969907 | O32: 0.74 | P32: =O32-N32 -> 0.00030092593 | Q32: 775 | S32: 0.83158565 | T32: 0.831875 | U32: =T32-S32 -> 0.00028935185 | V32: 803
B33: 43151 | C33: 50.4kW | D33: -1.0 GeV/c | E33: production run | F33: 0 | G33: 1 | H33: =G33-F33 -> 1 | I33: =AJ110 -> 0.063761574 | J33: =H33-I33 -> 0.93623843 | K33: =J33/H33 -> 0.93623843 | N33: 0.76954861 | O33: 0.76987269 | P33: =O33-N33 -> 0.00032407407 | Q33: 776 | S33: 0.90813657 | T33: 0.9083912 | U33: =T33-S33 -> 0.00025462963 | V33: 804
B34: 43152 | C34: 50.4kW | D34: -1.0 GeV/c | E34: production run | F34: 0 | G34: 0.375 | H34: =G34-F34 -> 0.375 | I34: =AJ126 -> 0.068796296 | J34: =H34-I34 -> 0.3062037 | K34: =J34/H34 -> 0.81654321 | N34: 0.78086806 | O34: 0.78128472 | P34: =O34-N34 -> 0.00041666667 | Q34: 776 | S34: 0.91774306 | T34: 0.91804398 | U34: =T34-S34 -> 0.00030092593 | V34: 805
B35: 43153 | C35: 51.1kW | D35: -1.0 GeV/c | E35: production run | F35: 0.97803241 | G35: 1 | H35: =G35-F35 -> 0.021967593 | I35: 0 | J35: =H35-I35 -> 0.021967593 | K35: =J35/H35 -> 1 | N35: 0.79708333 | O35: 0.79743056 | P35: =O35-N35 -> 0.00034722222 | Q35: 777 | S35: 0.91905093 | T35: 0.91930556 | U35: =T35-S35 -> 0.00025462963 | V35: 805
B36: 43154 | C36: 51.1kW | D36: -1.0 GeV/c | E36: production run | F36: 0 | G36: 1 | H36: =G36-F36 -> 1 | I36: =P45 -> 0.063819444 | J36: =H36-I36 -> 0.93618056 | K36: =J36/H36 -> 0.93618056 | N36: 0.81505787 | O36: 0.81547454 | P36: =O36-N36 -> 0.00041666667 | Q36: 777 | S36: 0.92396991 | T36: 0.9244213 | U36: =T36-S36 -> 0.00045138889 | V36: 805
B37: 43155 | C37: 51.1kW | D37: -1.0 GeV/c | E37: production run | F37: 0 | G37: 1 | H37: =G37-F37 -> 1 | I37: =U40 -> 0.085462963 | J37: =H37-I37 -> 0.91453704 | K37: =J37/H37 -> 0.91453704 | N37: 0.8193287 | O37: 0.8196412 | P37: =O37-N37 -> 0.0003125 | Q37: 777 | S37: 0.96159722 | T37: 0.96196759 | U37: =T37-S37 -> 0.00037037037 | V37: 806
B38: 43156 | C38: 51.1kW | D38: -1.0 GeV/c | E38: production run | F38: 0 | G38: 0.23123843 | H38: =G38-F38 -> 0.23123843 | I38: =Z10 -> 0.010798611 | J38: =H38-I38 -> 0.22043981 | K38: =J38/H38 -> 0.95330097 | N38: 0.82554398 | O38: 0.82582176 | P38: =O38-N38 -> 0.00027777778 | Q38: 777 | S38: 0.98009259 | T38: 0.98043981 | U38: =T38-S38 -> 0.00034722222 | V38: 806
E39: sum | H39: =SUM(H4:H38) -> 21.477187 | I39: =SUM(I4:I38) -> 3.0182755 | J39: =SUM(J4:J38) -> 18.458912 | K39: =J39/H39 -> 0.85946598 | N39: 0.86528935 | O39: 0.87331019 | P39: =O39-N39 -> 0.0080208333 | Q39: 778end | S39: 0.99109954 | T39: 0.99163194 | U39: =T39-S39 -> 0.00053240741 | V39: 806
N40: 0.91398148 | O40: 0.91430556 | P40: =O40-N40 -> 0.00032407407 | Q40: 779 | T40: total | U40: =SUM(U4:U39) -> 0.085462963
N41: 0.91996528 | O41: 0.92079861 | P41: =O41-N41 -> 0.00083333333 | Q41: 780
...

Sheet summary
A1: run num | B1: date | C1: starttime | E1: starttime | F1: start time | G1: endtime | H1: duration | I1: Acc power | J1: exp. target | K1: HD-Target | L1: Beam Pol | M1: K1.8D1 | N1: K1.8mom | O1: ESS | P1: CM (1/2) | Q1: beam | R1: Trig | S1: 1st trig Req | T1: 1st trig Acc | U1: Solenoid | V1: Ushiwaka | W1: FT | X1: SYIM | Y1: TM | Z1: beam | AA1: kaon | AB1: pion | AC1: MomS+ | AD1: MomS- | AE1: MS+ | AF1: MS- | AG1: IF-H + | AH1: IF-H- | AI1: IF-V + | AJ1: IF-V- | AK1: DEF | AL1: Comment | AM1: Log Note | AN1: k- purity | AO1: K- on target (DEF) | AP1: K- on target (DEF*0.7) | AQ1: Integrated K- on target (DEF*0.7) | AR1: integrated time | AS1: kW*week | AT1: integrated kW*week | AU1: true K /spill | AV1: true pi /spill | AW1: K/pi
A2: 0 | F2: 43117.75 | G2: 43117.75 | H2: 0 | I2: 10.45 | K2: Au | L2: negative | M2: -369 | N2: 1 | O2: 200 | P2: 345 | Q2: K | R2: beam | AC2: 160.2 | AD2: -110 | AE2: 3.3 | AF2: -1.42 | AG2: 109.8 | AH2: -110.1 | AI2: 3.81 | AJ2: -0.26 | AL2: junk | AM2: Main Log vol.38
A3: 1 | F3: 43117.75 | G3: 43117.75 | H3: 0 | I3: 10.45 | K3: Au | L3: negative | M3: -369 | N3: 1 | O3: 200 | P3: 345 | Q3: K | R3: beam | V3: 1700~2200 | AC3: 160.2 | AD3: -110 | AE3: 3.3 | AF3: -1.42 | AG3: 109.8 | AH3: -110.1 | AI3: 3.81 | AJ3: -0.26 | AL3: [USKW scan] 1700~2200, collector dead
A4: 2 | F4: 43117.75 | G4: 43117.75 | H4: 0 | I4: 10.45 | K4: Au | L4: negative | M4: -369 | N4: 1 | O4: 200 | P4: 345 | Q4: K | R4: beam | V4: 2100 | AC4: 160.2 | AD4: -110 | AE4: 3.3 | AF4: -1.42 | AG4: 109.8 | AH4: -110.1 | AI4: 3.81 | AJ4: -0.26 | AL4: [USKW scan] 2100, for SKS-TOF
A5: 3 | B5: ######## | C5: 0.027777778 | D5: 40473 | E5: 0.027778 | F5: 43117.75 | G5: 43117.75 | H5: 0 | I5: 10.45 | K5: Au | L5: negative | M5: -369 | N5: 1 | O5: 200 | P5: 345 | Q5: K | R5: beam | V5: 700~ | AC5: 160.2 | AD5: -110 | AE5: 3.3 | AF5: -1.42 | AG5: 109.8 | AH5: -110.1 | AI5: 3.81 | AJ5: -0.26 | AL5: junk
A6: 4 | B6: ######## | C6: 0.027777778 | D6: 40473 | E6: 0.027778 | F6: 43118.542 | G6: 43118.542 | H6: =G6-F6 -> 0 | I6: 31.56 | K6: Au | L6: negative | M6: -369 | N6: 1 | O6: 200 | P6: 345 | Q6: K | R6: K, beam/5 | AC6: 160.2 | AD6: -110 | AE6: 3.3 | AF6: -1.42 | AG6: 109.8 | AH6: -110 | AI6: 3.81 | AJ6: -0.26 | AL6: [BLDC study] default setting
A7: 5 | B7: ######## | C7: 0.22222222 | D7: 40473 | E7: 0.222222 | F7: 43118.542 | G7: 43118.542 | H7: =G7-F7 -> 0 | I7: 31.56 | K7: Au | L7: negative | M7: -369 | N7: 1 | O7: 200 | P7: 345 | Q7: K | R7: pi | AC7: 160.2 | AD7: -110 | AE7: 3.3 | AF7: -1.42 | AG7: 109.8 | AH7: -110 | AI7: 3.81 | AJ7: -0.26 | AL7: [BLDC study] default setting
A8: 6 | B8: ######## | C8: 0.27222222 | D8: 40473 | E8: 0.272222 | F8: 43118.542 | G8: 43118.542 | H8: =G8-F8 -> 0 | I8: 31.56 | K8: Au | L8: negative | M8: -369 | N8: 1 | O8: 200 | P8: 345 | Q8: K | R8: pi | AC8: 160.2 | AD8: -110 | AE8: 3.3 | AF8: -1.42 | AG8: 109.8 | AH8: -110 | AI8: 3.81 | AJ8: -0.26 | AL8: [BLDC study] scan
A9: 7 | B9: ######## | C9: 0.18125 | D9: 40474 | E9: 0.18125 | F9: 43118.542 | G9: 43118.542 | H9: =G9-F9 -> 0 | I9: 31.56 | K9: Au | L9: negative | M9: -369 | N9: 1 | O9: 200 | P9: 345 | Q9: K | R9: pi | AC9: 160.2 | AD9: -110 | AE9: 3.3 | AF9: -1.42 | AG9: 109.8 | AH9: -110 | AI9: 3.81 | AJ9: -0.26 | AL9: [BLDC study] scan
A10: 8 | B10: ######## | C10: 0.21527778 | D10: 40474 | E10: 0.215278 | F10: 43118.542 | G10: 43118.542 | H10: =G10-F10 -> 0 | I10: 31.56 | K10: Au | L10: negative | M10: -369 | N10: 1 | O10: 200 | P10: 345 | Q10: K | R10: pi | AC10: 160.2 | AD10: -110 | AE10: 3.3 | AF10: -1.42 | AG10: 109.8 | AH10: -110 | AI10: 3.81 | AJ10: -0.26 | AL10: [BLDC study] scan
A11: 9 | B11: ######## | C11: 0.23611111 | D11: 40474 | E11: 0.236111 | F11: 43118.542 | G11: 43118.542 | H11: =G11-F11 -> 0 | I11: 31.56 | K11: Au | L11: negative | M11: -369 | N11: 1 | O11: 200 | P11: 345 | Q11: K | R11: pi | AC11: 160.2 | AD11: -110 | AE11: 3.3 | AF11: -1.42 | AG11: 109.8 | AH11: -110 | AI11: 3.81 | AJ11: -0.26 | AL11: [BLDC study] scan
A12: 10 | B12: ######## | C12: 0.25833333 | D12: 40474 | E12: 0.258333 | F12: 43118.542 | G12: 43118.542 | H12: =G12-F12 -> 0 | I12: 31.56 | K12: Au | L12: negative | M12: -369 | N12: 1 | O12: 200 | P12: 345 | Q12: K | R12: pi | AC12: 160.2 | AD12: -110 | AE12: 3.3 | AF12: -1.42 | AG12: 109.8 | AH12: -110 | AI12: 3.81 | AJ12: -0.26 | AL12: [BLDC study] scan
A13: 11 | B13: ######## | C13: 0.28194444 | D13: 40474 | E13: 0.281944 | F13: 43118.542 | G13: 43118.542 | H13: =G13-F13 -> 0 | I13: 31.56 | K13: Au | L13: negative | M13: -369 | N13: 1 | O13: 200 | P13: 345 | Q13: K | R13: pi | AC13: 160.2 | AD13: -110 | AE13: 3.3 | AF13: -1.42 | AG13: 109.8 | AH13: -110 | AI13: 3.81 | AJ13: -0.26 | AL13: [BLDC study] scan
A14: 12 | B14: ######## | C14: 0.30555556 | D14: 40474 | E14: 0.305556 | F14: 43118.542 | G14: 43118.542 | H14: =G14-F14 -> 0 | I14: 31.56 | K14: Au | L14: negative | M14: -369 | N14: 1 | O14: 200 | P14: 345 | Q14: K | R14: pi | AC14: 160.2 | AD14: -110 | AE14: 3.3 | AF14: -1.42 | AG14: 109.8 | AH14: -110 | AI14: 3.81 | AJ14: -0.26 | AL14: [BLDC study] scan
A15: 13 | B15: ######## | C15: 0.32430556 | D15: 40474 | E15: 0.324306 | F15: 43118.542 | G15: 43118.542 | H15: =G15-F15 -> 0 | I15: 31.56 | K15: Au | L15: negative | M15: -369 | N15: 1 | O15: 200 | P15: 345 | Q15: K | R15: pi | AC15: 160.2 | AD15: -110 | AE15: 3.3 | AF15: -1.42 | AG15: 109.8 | AH15: -110 | AI15: 3.81 | AJ15: -0.26 | AL15: [BLDC study] scan
A16: 14 | B16: ######## | C16: 0.34652778 | D16: 40474 | E16: 0.346528 | F16: 43118.542 | G16: 43118.542 | H16: =G16-F16 -> 0 | I16: 31.56 | K16: Au | L16: negative | M16: -369 | N16: 1 | O16: 200 | P16: 345 | Q16: K | R16: pi | AC16: 160.2 | AD16: -110 | AE16: 3.3 | AF16: -1.42 | AG16: 109.8 | AH16: -110 | AI16: 3.81 | AJ16: -0.26 | AL16: [BLDC study] scan
A17: 15 | F17: 43118.542 | G17: 43118.542 | H17: =G17-F17 -> 0 | I17: 31.56 | K17: Au | L17: negative | M17: -369 | N17: 1 | O17: 200 | P17: 345 | Q17: K | R17: pi | AC17: 160.2 | AD17: -110 | AE17: 3.3 | AF17: -1.42 | AG17: 109.8 | AH17: -110 | AI17: 3.81 | AJ17: -0.26 | AL17: [BLDC study] scan
A18: 16 | B18: ######## | C18: 0.41319444 | D18: 40474 | E18: 0.413194 | F18: 43118.542 | G18: 43118.542 | H18: =G18-F18 -> 0 | I18: 31.56 | K18: Au | L18: negative | M18: -369 | N18: 1 | O18: 200 | P18: 345 | Q18: K | R18: pi | AC18: 160.2 | AD18: -110 | AE18: 3.3 | AF18: -1.42 | AG18: 109.8 | AH18: -110 | AI18: 3.81 | AJ18: -0.26 | AL18: [BLDC study] scan
A19: 17 | B19: ######## | C19: 0.39097222 | D19: 40474 | E19: 0.390972 | F19: 43118.542 | G19: 43118.542 | H19: =G19-F19 -> 0 | I19: 31.56 | K19: Au | L19: negative | M19: -369 | N19: 1 | O19: 200 | P19: 345 | Q19: K | R19: pi | AC19: 160.2 | AD19: -110 | AE19: 3.3 | AF19: -1.42 | AG19: 109.8 | AH19: -110 | AI19: 3.81 | AJ19: -0.26 | AL19: [BLDC study] scan
A20: 18 | B20: ######## | C20: 0.45833333 | D20: 40474 | E20: 0.458333 | F20: 43118.542 | G20: 43118.542 | H20: =G20-F20 -> 0 | I20: 31.56 | K20: Au | L20: negative | M20: -369 | N20: 1 | O20: 200 | P20: 345 | Q20: K | R20: pi | AC20: 160.2 | AD20: -110 | AE20: 3.3 | AF20: -1.42 | AG20: 109.8 | AH20: -110 | AI20: 3.81 | AJ20: -0.26 | AL20: [BLDC study] scan
A21: 19 | B21: ######## | C21: 0.48263889 | D21: 40474 | E21: 0.482639 | F21: 43118.542 | G21: 43118.542 | H21: =G21-F21 -> 0 | I21: 31.56 | K21: Au | L21: negative | M21: -369 | N21: 1 | O21: 200 | P21: 345 | Q21: K | R21: pi | AC21: 160.2 | AD21: -110 | AE21: 3.3 | AF21: -1.42 | AG21: 109.8 | AH21: -110 | AI21: 3.81 | AJ21: -0.26 | AL21: [BLDC study] scan
A22: 20 | B22: ######## | C22: 0.50347222 | D22: 40474 | E22: 0.503472 | F22: 43118.542 | G22: 43118.542 | H22: =G22-F22 -> 0 | I22: 31.56 | K22: Au | L22: negative | M22: -369 | N22: 1 | O22: 200 | P22: 345 | Q22: K | R22: pi | AC22: 160.2 | AD22: -110 | AE22: 3.3 | AF22: -1.42 | AG22: 109.8 | AH22: -110 | AI22: 3.81 | AJ22: -0.26 | AL22: [BLDC study] scan
A23: 21 | B23: ######## | C23: 0.54791667 | D23: 40474 | E23: 0.547917 | F23: 43118.542 | G23: 43118.542 | H23: =G23-F23 -> 0 | I23: 31.56 | K23: Au | L23: negative | M23: -369 | N23: 1 | O23: 200 | P23: 345 | Q23: K | R23: CDH1*pi, CDH1*K | AC23: 160.2 | AD23: -110 | AE23: 3.3 | AF23: -1.42 | AG23: 109.8 | AH23: -110 | AI23: 3.81 | AJ23: -0.26 | AL23: junk
A24: 22 | F24: 43118.542 | G24: 43118.542 | H24: =G24-F24 -> 0 | I24: 31.56 | K24: Au | L24: negative | M24: -369 | N24: 1 | O24: 200 | P24: 345 | Q24: K | R24: pi | U24: 983 | V24: 1600 | AC24: 160.2 | AD24: -110 | AE24: 3.3 | AF24: -1.42 | AG24: 109.8 | AH24: -110 | AI24: 3.81 | AJ24: -0.26 | AL24: [CDC study] Vth=0.60V, Dora=+938
A25: 23 | F25: 43118.542 | G25: 43118.542 | H25: =G25-F25 -> 0 | I25: 31.56 | K25: Au | L25: negative | M25: -369 | N25: 1 | O25: 200 | P25: 345 | Q25: K | R25: pi | U25: 983 | V25: 1600 | AC25: 160.2 | AD25: -110 | AE25: 3.3 | AF25: -1.42 | AG25: 109.8 | AH25: -110 | AI25: 3.81 | AJ25: -0.26 | AL25: [CDC study] Vth=0.45V, Dora=+938
A26: 24 | B26: ######## | C26: 0.59375 | D26: 40474 | E26: 0.59375 | F26: 43118.542 | G26: 43118.542 | H26: =G26-F26 -> 0 | I26: 31.56 | K26: Au | L26: negative | M26: -369 | N26: 1 | O26: 200 | P26: 345 | Q26: K | R26: pi | U26: 983 | V26: 1600 | AC26: 160.2 | AD26: -110 | AE26: 3.3 | AF26: -1.42 | AG26: 109.8 | AH26: -110 | AI26: 3.81 | AJ26: -0.26 | AL26: [CDC study] Vth=0.75V, Dora=+938
A27: 25 | F27: 43118.542 | G27: 43118.542 | H27: =G27-F27 -> 0 | I27: 31.56 | K27: Au | L27: negative | M27: -369 | N27: 1 | O27: 200 | P27: 345 | Q27: K | R27: pi | U27: 0 | V27: 0 | AC27: 160.2 | AD27: -110 | AE27: 3.3 | AF27: -1.42 | AG27: 109.8 | AH27: -110 | AI27: 3.81 | AJ27: -0.26 | AL27: [CDC study] Vth=0.60V, Dora=0, USWK=0
A28: 26 | B28: ######## | C28: 0.64513889 | D28: 40474 | E28: 0.645139 | F28: 43118.542 | G28: 43118.542 | H28: =G28-F28 -> 0 | I28: 31.56 | K28: Au | L28: negative | M28: -369 | N28: 1 | O28: 200 | P28: 345 | Q28: K | R28: pi | U28: 0 | V28: 0 | AC28: 160.2 | AD28: -110 | AE28: 3.3 | AF28: -1.42 | AG28: 109.8 | AH28: -110 | AI28: 3.81 | AJ28: -0.26 | AL28: junk
A29: 27 | B29: ######## | C29: 0.66666667 | D29: 40474 | E29: 0.666667 | F29: 43118.542 | G29: 43118.542 | H29: =G29-F29 -> 0 | I29: 31.56 | K29: Au | L29: negative | M29: -369 | N29: 1 | O29: 200 | P29: 345 | Q29: K | R29: pi | V29: -1900~-1600 | AC29: 160.2 | AD29: -110 | AE29: 3.3 | AF29: -1.42 | AG29: 109.8 | AH29: -110 | AI29: 3.81 | AJ29: -0.26 | AL29: [USWK scan] -1900~-1600, collector dead
A30: 28 | F30: 43118.542 | G30: 43118.542 | H30: =G30-F30 -> 0 | I30: 31.56 | K30: Au | L30: negative | M30: -369 | N30: 1 | O30: 200 | P30: 345 | Q30: K | R30: pi | V30: -1600~-2100 | AC30: 160.2 | AD30: -110 | AE30: 3.3 | AF30: -1.42 | AG30: 109.8 | AH30: -110 | AI30: 3.81 | AJ30: -0.26 | AL30: [USWK scan] -1600~-2100, NC-TDC-U17 dead
A31: 29 | B31: ######## | C31: 0.71041667 | D31: 40474 | E31: 0.710417 | F31: 43118.542 | G31: 43118.542 | H31: =G31-F31 -> 0 | I31: 31.56 | K31: Au | L31: negative | M31: -369 | N31: 1 | O31: 200 | P31: 345 | Q31: K | R31: pi | AC31: 160.2 | AD31: -110 | AE31: 3.3 | AF31: -1.42 | AG31: 109.8 | AH31: -110 | AI31: 3.81 | AJ31: -0.26 | AL31: junk
A32: 30 | B32: ######## | C32: 0.73263889 | D32: 40474 | E32: 0.732639 | F32: 43118.542 | G32: 43118.542 | H32: =G32-F32 -> 0 | I32: 31.56 | K32: Au | L32: negative | M32: -369 | N32: 1 | O32: 200 | P32: 345 | Q32: K | R32: pi | V32: 700 | AC32: 160.2 | AD32: -110 | AE32: 3.3 | AF32: -1.42 | AG32: 109.8 | AH32: -110 | AI32: 3.81 | AJ32: -0.26 | AL32: [USWK scan] 700, NC-TDC-U17 fixed
A33: 31 | F33: 43118.542 | G33: 43118.542 | H33: =G33-F33 -> 0 | I33: 31.56 | K33: Au | L33: negative | M33: -369 | N33: 1 | O33: 200 | P33: 345 | Q33: K | R33: pi | AC33: 160.2 | AD33: -110 | AE33: 3.3 | AF33: -1.42 | AG33: 109.8 | AH33: -110 | AI33: 3.81 | AJ33: -0.26 | AK33: off | AL33: [D5 scan] -1866, BPD=default
A34: 32 | F34: 43118.542 | G34: 43118.542 | H34: =G34-F34 -> 0 | I34: 31.56 | K34: Au | L34: negative | M34: -369 | N34: 1 | O34: 200 | P34: 345 | Q34: K | R34: pi | AC34: 160.2 | AD34: -110 | AE34: 3.3 | AF34: -1.42 | AG34: 109.8 | AH34: -110 | AI34: 3.81 | AJ34: -0.26 | AK34: off | AL34: [D5 scan] -1866, BPD=-0.2V
A35: 33 | B35: ######## | C35: 0.83819444 | D35: 40474 | E35: 0.838194 | F35: 43118.542 | G35: 43118.542 | H35: =G35-F35 -> 0 | I35: 31.56 | K35: Au | L35: negative | M35: -369 | N35: 1 | O35: 200 | P35: 345 | Q35: K | R35: pi | AC35: 160.2 | AD35: -110 | AE35: 3.3 | AF35: -1.42 | AG35: 109.8 | AH35: -110 | AI35: 3.81 | AJ35: -0.26 | AK35: off | AL35: [D5 scan] -1866, BPD=+0.2V
A36: 34 | B36: ######## | C36: 0.85833333 | D36: 40474 | E36: 0.858333 | F36: 43118.542 | G36: 43118.542 | H36: =G36-F36 -> 0 | I36: 31.56 | K36: Au | L36: negative | M36: -369 | N36: 1 | O36: 200 | P36: 345 | Q36: K | R36: pi | AC36: 160.2 | AD36: -110 | AE36: 3.3 | AF36: -1.42 | AG36: 109.8 | AH36: -110 | AI36: 3.81 | AJ36: -0.26 | AK36: off | AL36: [D5 scan] -1866, BPD=+0.4V
A37: 35 | F37: 43118.542 | G37: 43118.542 | H37: =G37-F37 -> 0 | I37: 31.56 | K37: Au | L37: negative | M37: -369 | N37: 1 | O37: 200 | P37: 345 | Q37: K | R37: pi | AC37: 160.2 | AD37: -110 | AE37: 3.3 | AF37: -1.42 | AG37: 109.8 | AH37: -110 | AI37: 3.81 | AJ37: -0.26 | AK37: off | AL37: junk
A38: 36 | B38: ######## | C38: 0.90138889 | D38: 40474 | E38: 0.901389 | F38: 43118.542 | G38: 43118.542 | H38: =G38-F38 -> 0 | I38: 31.56 | K38: Au | L38: negative | M38: -369 | N38: 1 | O38: 200 | P38: 345 | Q38: K | R38: pi | AC38: 160.2 | AD38: -110 | AE38: 3.3 | AF38: -1.42 | AG38: 109.8 | AH38: -110 | AI38: 3.81 | AJ38: -0.26 | AK38: off | AL38: [D5 scan] -1366, BPD=+0.4V
A39: 37 | B39: ######## | C39: 0.92361111 | D39: 40474 | E39: 0.923611 | F39: 43118.542 | G39: 43118.542 | H39: =G39-F39 -> 0 | I39: 31.56 | K39: Au | L39: negative | M39: -369 | N39: 1 | O39: 200 | P39: 345 | Q39: K | R39: pi | AC39: 160.2 | AD39: -110 | AE39: 3.3 | AF39: -1.42 | AG39: 109.8 | AH39: -110 | AI39: 3.81 | AJ39: -0.26 | AK39: off | AL39: [D5 scan] -1366, BPD=+0.2V
A40: 38 | B40: ######## | C40: 0.94930556 | D40: 40474 | E40: 0.949306 | F40: 43118.542 | G40: 43118.542 | H40: =G40-F40 -> 0 | I40: 31.56 | K40: Au | L40: negative | M40: -369 | N40: 1 | O40: 200 | P40: 345 | Q40: K | R40: pi | AC40: 160.2 | AD40: -110 | AE40: 3.3 | AF40: -1.42 | AG40: 109.8 | AH40: -110 | AI40: 3.81 | AJ40: -0.26 | AK40: off | AL40: [D5 scan] -1366, BPD=default
...

Sheet expect_KOT
A1: 43155 | B1: =summary!$AQ$783 -> 3.6572419e+10
A2: KOT/h | B2: 98000000
C4: expected KOT | G4: integrated KOT
A5: date | B5: allocation | C5: 100% | D5: 90% | E5: 80% | F5: 70% | G5: 100% | H5: 90% | I5: 80% | J5: 70%
G6: =B1 -> 3.6572419e+10 | H6: =B1 -> 3.6572419e+10 | I6: =B1 -> 3.6572419e+10 | J6: =B1 -> 3.6572419e+10
A7: 43155.999 | B7: 24 | C7: =B7*$B$2 -> 2352000000 | D7: =C7*0.9 -> 2116800000 | E7: =C7*0.8 -> 1881600000 | F7: =C7*0.7 -> 1646400000 | G7: =G6+C7 -> 3.8924419e+10 | H7: =H6+D7 -> 3.8689219e+10 | I7: =I6+E7 -> 3.8454019e+10 | J7: =J6+F7 -> 3.8218819e+10
A8: 43156.999 | B8: 6 | C8: =B8*$B$2 -> 588000000 | D8: =C8*0.9 -> 529200000 | E8: =C8*0.8 -> 470400000 | F8: =C8*0.7 -> 411600000 | G8: =G7+C8 -> 3.9512419e+10 | H8: =H7+D8 -> 3.9218419e+10 | I8: =I7+E8 -> 3.8924419e+10 | J8: =J7+F8 -> 3.8630419e+10
A9: 43157.999 | B9: 0 | C9: =B9*$B$2 -> 0 | D9: =C9*0.9 -> 0 | E9: =C9*0.8 -> 0 | F9: =C9*0.7 -> 0 | G9: =G8+C9 -> 3.9512419e+10 | H9: =H8+D9 -> 3.9218419e+10 | I9: =I8+E9 -> 3.8924419e+10 | J9: =J8+F9 -> 3.8630419e+10

Sheet expect_kW
A1: 43155 | B1: =summary!$AT$783 -> 112.04063
A2: kW*week/h | B2: 0.29
C4: expected KOT | G4: integrated KOT
A5: date | B5: allocation | C5: 100% | D5: 90% | E5: 80% | F5: 70% | G5: 100% | H5: 90% | I5: 80% | J5: 70%
G6: =B1 -> 112.04063 | H6: =B1 -> 112.04063 | I6: =B1 -> 112.04063 | J6: =B1 -> 112.04063
A7: 43155.999 | B7: 24 | C7: =B7*$B$2 -> 6.96 | D7: =C7*0.9 -> 6.264 | E7: =C7*0.8 -> 5.568 | F7: =C7*0.7 -> 4.872 | G7: =G6+C7 -> 119.00063 | H7: =H6+D7 -> 118.30463 | I7: =I6+E7 -> 117.60863 | J7: =J6+F7 -> 116.91263
A8: 43156.999 | B8: 6 | C8: =B8*$B$2 -> 1.74 | D8: =C8*0.9 -> 1.566 | E8: =C8*0.8 -> 1.392 | F8: =C8*0.7 -> 1.218 | G8: =G7+C8 -> 120.74063 | H8: =H7+D8 -> 119.87063 | I8: =I7+E8 -> 119.00063 | J8: =J7+F8 -> 118.13063
A9: 43157.999 | B9: 0 | C9: =B9*$B$2 -> 0 | D9: =C9*0.9 -> 0 | E9: =C9*0.8 -> 0 | F9: =C9*0.7 -> 0 | G9: =G8+C9 -> 120.74063 | H9: =H8+D9 -> 119.87063 | I9: =I8+E9 -> 119.00063 | J9: =J8+F9 -> 118.13063
